Workbook

Sheet Resumen
A1: UNMdP Map · Ciencias Económicas y Sociales
A3: Carrera | B3: Plan | C3: Materias | D3: Aprobadas | E3: Cursadas aprobadas | F3: Puedo cursar | G3: Bloqueadas
A4: Contador Público | B4: Plan E (2005) · OCS 446/2018 | C4: =COUNTA('Contador Público'!F2:F46) -> 45 | D4: =COUNTIF('Contador Público'!Q2:Q46,"Aprobada") -> 0 | E4: =COUNTIF('Contador Público'!Q2:Q46,"Cursada aprobada") -> 0 | F4: =COUNTIF('Contador Público'!R2:R46,"Sí") -> 16 | G4: =COUNTIF('Contador Público'!R2:R46,"No") -> 29
A5: Licenciatura en Administración | B5: Plan C (2005) · OCS 881/2004 | C5: =COUNTA('Lic. Administración'!F2:F46) -> 45 | D5: =COUNTIF('Lic. Administración'!Q2:Q46,"Aprobada") -> 0 | E5: =COUNTIF('Lic. Administración'!Q2:Q46,"Cursada aprobada") -> 0 | F5: =COUNTIF('Lic. Administración'!R2:R46,"Sí") -> 15 | G5: =COUNTIF('Lic. Administración'!R2:R46,"No") -> 30
A6: Licenciatura en Economía | B6: Plan E (2005) · RM 1281/2019 | C6: =COUNTA('Lic. Economía'!F2:F46) -> 45 | D6: =COUNTIF('Lic. Economía'!Q2:Q46,"Aprobada") -> 0 | E6: =COUNTIF('Lic. Economía'!Q2:Q46,"Cursada aprobada") -> 0 | F6: =COUNTIF('Lic. Economía'!R2:R46,"Sí") -> 18 | G6: =COUNTIF('Lic. Economía'!R2:R46,"No") -> 27
A7: Licenciatura en Turismo | B7: Plan E (2005) · OCS 370/2004 y 513/2009 | C7: =COUNTA('Lic. Turismo'!F2:F46) -> 45 | D7: =COUNTIF('Lic. Turismo'!Q2:Q46,"Aprobada") -> 0 | E7: =COUNTIF('Lic. Turismo'!Q2:Q46,"Cursada aprobada") -> 0 | F7: =COUNTIF('Lic. Turismo'!R2:R46,"Sí") -> 23 | G7: =COUNTIF('Lic. Turismo'!R2:R46,"No") -> 22
A8: Profesorado Universitario en Economía | B8: OCA 2344/2011 y 125/2018 | C8: =COUNTA('Prof. Economía'!F2:F51) -> 50 | D8: =COUNTIF('Prof. Economía'!Q2:Q51,"Aprobada") -> 0 | E8: =COUNTIF('Prof. Economía'!Q2:Q51,"Cursada aprobada") -> 0 | F8: =COUNTIF('Prof. Economía'!R2:R51,"Sí") -> 17 | G8: =COUNTIF('Prof. Economía'!R2:R51,"No") -> 33
A9: Tecnicatura Universitaria Contable | B9: RM 435/2020 | C9: =COUNTA('Tec. Contable'!F2:F25) -> 24 | D9: =COUNTIF('Tec. Contable'!Q2:Q25,"Aprobada") -> 0 | E9: =COUNTIF('Tec. Contable'!Q2:Q25,"Cursada aprobada") -> 0 | F9: =COUNTIF('Tec. Contable'!R2:R25,"Sí") -> 4 | G9: =COUNTIF('Tec. Contable'!R2:R25,"No") -> 20
A10: Tecnicatura Universitaria en Comercialización | B10: OCS 1569/2015 · RM 875/2016 | C10: =COUNTA('Tec. Comercialización'!F2:F26) -> 25 | D10: =COUNTIF('Tec. Comercialización'!Q2:Q26,"Aprobada") -> 0 | E10: =COUNTIF('Tec. Comercialización'!Q2:Q26,"Cursada aprobada") -> 0 | F10: =COUNTIF('Tec. Comercialización'!R2:R26,"Sí") -> 6 | G10: =COUNTIF('Tec. Comercialización'!R2:R26,"No") -> 19
A11: Tecnicatura Universitaria en Comercio Exterior | B11: OCS 2226/2016 · RM 2625/2017 | C11: =COUNTA('Tec. Comercio Exterior'!F2:F26) -> 25 | D11: =COUNTIF('Tec. Comercio Exterior'!Q2:Q26,"Aprobada") -> 0 | E11: =COUNTIF('Tec. Comercio Exterior'!Q2:Q26,"Cursada aprobada") -> 0 | F11: =COUNTIF('Tec. Comercio Exterior'!R2:R26,"Sí") -> 6 | G11: =COUNTIF('Tec. Comercio Exterior'!R2:R26,"No") -> 19
A12: Tecnicatura Universitaria en Periodismo Digital | B12: OCS 2322/2017 | C12: =COUNTA('Tec. Periodismo Digital'!F2:F26) -> 25 | D12: =COUNTIF('Tec. Periodismo Digital'!Q2:Q26,"Aprobada") -> 0 | E12: =COUNTIF('Tec. Periodismo Digital'!Q2:Q26,"Cursada aprobada") -> 0 | F12: =COUNTIF('Tec. Periodismo Digital'!R2:R26,"Sí") -> 10 | G12: =COUNTIF('Tec. Periodismo Digital'!R2:R26,"No") -> 15
A13: Tecnicatura Universitaria en Turismo | B13: OCA 1902/2015 · RM 518/2017 | C13: =COUNTA('Tec. Turismo'!F2:F29) -> 28 | D13: =COUNTIF('Tec. Turismo'!Q2:Q29,"Aprobada") -> 0 | E13: =COUNTIF('Tec. Turismo'!Q2:Q29,"Cursada aprobada") -> 0 | F13: =COUNTIF('Tec. Turismo'!R2:R29,"Sí") -> 8 | G13: =COUNTIF('Tec. Turismo'!R2:R29,"No") -> 20
A15: Para cursar, las correlativas tienen que tener: | B15: La cursada aprobada
A17: Cómo usar: en la hoja de tu carrera cambiá la columna Estado (texto azul): No cursada, Cursada aprobada o Aprobada.
A18: ¿Puedo cursar? muestra Sí cuando las correlativas cumplen la regla elegida arriba (celda amarilla).
A19: ¿Puedo rendir el final? aparece en las materias con la cursada aprobada: Sí cuando todas sus correlativas están Aprobada.
A20: Una materia nunca puede estar Aprobada si alguna correlativa no lo está. La columna Correlativas a revisar marca en rojo esos casos.
A21: La cursada aprobada tiene un año de vigencia (OCA 357/2025).
A22: Los códigos de correlativas que no figuran en el plan no se tienen en cuenta (tienen un comentario).
A23: Fuente: planes de estudio publicados en eco.mdp.edu.ar (clic en el nombre de la carrera). Verificá con la facultad.

Sheet Contador Público
A1: Ciclo | B1: Orientación / Grupo | C1: Año | D1: Cuat. | E1: Área | F1: Cód. | G1: Denominación | H1: Grupo | I1: Hs/s | J1: Hs Bim | K1: Hs Cuat | L1: Corr. 1 | M1: Corr. 2 | N1: Corr. 3 | O1: Corr. 4 | P1: Corr. 5 | Q1: Estado | R1: ¿Puedo cursar? | S1: Correlativas pendientes | T1: ¿Puedo rendir el final? | U1: Correlativas a revisar
A2: Ciclo básico | C2: 1 | D2: 1 | E2: EC | F2: 101 | G2: Introducción a la Economía | H2: I | I2: 6 | K2: 96 | Q2: No cursada | R2: =IF(Q2="Aprobada","Ya aprobada",IF(Q2="Cursada aprobada","Ya cursada",IF(AND(OR(L2="",COUNTIF($F$2:$F$46,L2)=0,COUNTIFS($F$2:$F$46,L2,$Q$2:$Q$46,"Aprobada")>0,AND(Resumen!$B$15="La cursada aprobada",COUNTIFS($F$2:$F$46,L2,$Q$2:$Q$46,"Cursada aprobada")>0)),OR(M2="",COUNTIF($F$2:$F$46,M2)=0,COUNTIFS($F$2:$F$46,M2,$Q$2:$Q$46,"Aprobada")>0,AND(Resumen!$B$15="La cursada aprobada",COUNTIFS($F$2:$F$46,M2,$Q$2:$Q$46,"Cursada aprobada")>0)),OR(N2="",COUNTIF($F$2:$F$46,N2)=0,COUNTIFS($F$2:$F$46,N2,$Q$2:$Q$46,"Aprobada")>0,AND(Resumen!$B$15="La cursada aprobada",COUNTIFS($F$2:$F$46,N2,$Q$2:$Q$46,"Cursada aprobada")>0)),OR(O2="",COUNTIF($F$2:$F$46,O2)=0,COUNTIFS($F$2:$F$46,O2,$Q$2:$Q$46,"Aprobada")>0,AND(Resumen!$B$15="La cursada aprobada",COUNTIFS($F$2:$F$46,O2,$Q$2:$Q$46,"Cursada aprobada")>0)),OR(P2="",COUNTIF($F$2:$F$46,P2)=0,COUNTIFS($F$2:$F$46,P2,$Q$2:$Q$46,"Aprobada")>0,AND(Resumen!$B$15="La cursada aprobada",COUNTIFS($F$2:$F$46,P2,$Q$2:$Q$46,"Cursada aprobada")>0))),"Sí","No"))) -> Sí | S2: =TRIM(IF(NOT(OR(L2="",COUNTIF($F$2:$F$46,L2)=0,COUNTIFS($F$2:$F$46,L2,$Q$2:$Q$46,"Aprobada")>0,AND(Resumen!$B$15="La cursada aprobada",COUNTIFS($F$2:$F$46,L2,$Q$2:$Q$46,"Cursada aprobada")>0))),L2&" ","")&IF(NOT(OR(M2="",COUNTIF($F$2:$F$46,M2)=0,COUNTIFS($F$2:$F$46,M2,$Q$2:$Q$46,"Aprobada")>0,AND(Resumen!$B$15="La cursada aprobada",COUNTIFS($F$2:$F$46,M2,$Q$2:$Q$46,"Cursada aprobada")>0))),M2&" ","")&IF(NOT(OR(N2="",COUNTIF($F$2:$F$46,N2)=0,COUNTIFS($F$2:$F$46,N2,$Q$2:$Q$46,"Aprobada")>0,AND(Resumen!$B$15="La cursada aprobada",COUNTIFS($F$2:$F$46,N2,$Q$2:$Q$46,"Cursada aprobada")>0))),N2&" ","")&IF(NOT(OR(O2="",COUNTIF($F$2:$F$46,O2)=0,COUNTIFS($F$2:$F$46,O2,$Q$2:$Q$46,"Aprobada")>0,AND(Resumen!$B$15="La cursada aprobada",COUNTIFS($F$2:$F$46,O2,$Q$2:$Q$46,"Cursada aprobada")>0))),O2&" ","")&IF(NOT(OR(P2="",COUNTIF($F$2:$F$46,P2)=0,COUNTIFS($F$2:$F$46,P2,$Q$2:$Q$46,"Aprobada")>0,AND(Resumen!$B$15="La cursada aprobada",COUNTIFS($F$2:$F$46,P2,$Q$2:$Q$46,"Cursada aprobada")>0))),P2&" ","")) | T2: =IF(Q2="Cursada aprobada",IF(AND(OR(L2="",COUNTIF($F$2:$F$46,L2)=0,COUNTIFS($F$2:$F$46,L2,$Q$2:$Q$46,"Aprobada")>0),OR(M2="",COUNTIF($F$2:$F$46,M2)=0,COUNTIFS($F$2:$F$46,M2,$Q$2:$Q$46,"Aprobada")>0),OR(N2="",COUNTIF($F$2:$F$46,N2)=0,COUNTIFS($F$2:$F$46,N2,$Q$2:$Q$46,"Aprobada")>0),OR(O2="",COUNTIF($F$2:$F$46,O2)=0,COUNTIFS($F$2:$F$46,O2,$Q$2:$Q$46,"Aprobada")>0),OR(P2="",COUNTIF($F$2:$F$46,P2)=0,COUNTIFS($F$2:$F$46,P2,$Q$2:$Q$46,"Aprobada")>0)),"Sí","No"),"") | U2: =IF(Q2="Aprobada",TRIM(IF(NOT(OR(L2="",COUNTIF($F$2:$F$46,L2)=0,COUNTIFS($F$2:$F$46,L2,$Q$2:$Q$46,"Aprobada")>0)),L2&" ","")&IF(NOT(OR(M2="",COUNTIF($F$2:$F$46,M2)=0,COUNTIFS($F$2:$F$46,M2,$Q$2:$Q$46,"Aprobada")>0)),M2&" ","")&IF(NOT(OR(N2="",COUNTIF($F$2:$F$46,N2)=0,COUNTIFS($F$2:$F$46,N2,$Q$2:$Q$46,"Aprobada")>0)),N2&" ","")&IF(NOT(OR(O2="",COUNTIF($F$2:$F$46,O2)=0,COUNTIFS($F$2:$F$46,O2,$Q$2:$Q$46,"Aprobada")>0)),O2&" ","")&IF(NOT(OR(P2="",COUNTIF($F$2:$F$46,P2)=0,COUNTIFS($F$2:$F$46,P2,$Q$2:$Q$46,"Aprobada")>0)),P2&" ","")),IF(Q2="Cursada aprobada",TRIM(IF(NOT(OR(L2="",COUNTIF($F$2:$F$46,L2)=0,COUNTIFS($F$2:$F$46,L2,$Q$2:$Q$46,"Aprobada")>0,AND(Resumen!$B$15="La cursada aprobada",COUNTIFS($F$2:$F$46,L2,$Q$2:$Q$46,"Cursada aprobada")>0))),L2&" ","")&IF(NOT(OR(M2="",COUNTIF($F$2:$F$46,M2)=0,COUNTIFS($F$2:$F$46,M2,$Q$2:$Q$46,"Aprobada")>0,AND(Resumen!$B$15="La cursada aprobada",COUNTIFS($F$2:$F$46,M2,$Q$2:$Q$46,"Cursada aprobada")>0))),M2&" ","")&IF(NOT(OR(N2="",COUNTIF($F$2:$F$46,N2)=0,COUNTIFS($F$2:$F$46,N2,$Q$2:$Q$46,"Aprobada")>0,AND(Resumen!$B$15="La cursada aprobada",COUNTIFS($F$2:$F$46,N2,$Q$2:$Q$46,"Cursada aprobada")>0))),N2&" ","")&IF(NOT(OR(O2="",COUNTIF($F$2:$F$46,O2)=0,COUNTIFS($F$2:$F$46,O2,$Q$2:$Q$46,"Aprobada")>0,AND(Resumen!$B$15="La cursada aprobada",COUNTIFS($F$2:$F$46,O2,$Q$2:$Q$46,"Cursada aprobada")>0))),O2&" ","")&IF(NOT(OR(P2="",COUNTIF($F$2:$F$46,P2)=0,COUNTIFS($F$2:$F$46,P2,$Q$2:$Q$46,"Aprobada")>0,AND(Resumen!$B$15="La cursada aprobada",COUNTIFS($F$2:$F$46,P2,$Q$2:$Q$46,"Cursada aprobada")>0))),P2&" ","")),""))
A3: Ciclo básico | C3: 1 | D3: 1 | E3: AD | F3: 104 | G3: Principios de Administración | H3: I | I3: 6 | K3: 96 | Q3: No cursada | R3: =IF(Q3="Aprobada","Ya aprobada",IF(Q3="Cursada aprobada","Ya cursada",IF(AND(OR(L3="",COUNTIF($F$2:$F$46,L3)=0,COUNTIFS($F$2:$F$46,L3,$Q$2:$Q$46,"Aprobada")>0,AND(Resumen!$B$15="La cursada aprobada",COUNTIFS($F$2:$F$46,L3,$Q$2:$Q$46,"Cursada aprobada")>0)),OR(M3="",COUNTIF($F$2:$F$46,M3)=0,COUNTIFS($F$2:$F$46,M3,$Q$2:$Q$46,"Aprobada")>0,AND(Resumen!$B$15="La cursada aprobada",COUNTIFS($F$2:$F$46,M3,$Q$2:$Q$46,"Cursada aprobada")>0)),OR(N3="",COUNTIF($F$2:$F$46,N3)=0,COUNTIFS($F$2:$F$46,N3,$Q$2:$Q$46,"Aprobada")>0,AND(Resumen!$B$15="La cursada aprobada",COUNTIFS($F$2:$F$46,N3,$Q$2:$Q$46,"Cursada aprobada")>0)),OR(O3="",COUNTIF($F$2:$F$46,O3)=0,COUNTIFS($F$2:$F$46,O3,$Q$2:$Q$46,"Aprobada")>0,AND(Resumen!$B$15="La cursada aprobada",COUNTIFS($F$2:$F$46,O3,$Q$2:$Q$46,"Cursada aprobada")>0)),OR(P3="",COUNTIF($F$2:$F$46,P3)=0,COUNTIFS($F$2:$F$46,P3,$Q$2:$Q$46,"Aprobada")>0,AND(Resumen!$B$15="La cursada aprobada",COUNTIFS($F$2:$F$46,P3,$Q$2:$Q$46,"Cursada aprobada")>0))),"Sí","No"))) -> Sí | S3: =TRIM(IF(NOT(OR(L3="",COUNTIF($F$2:$F$46,L3)=0,COUNTIFS($F$2:$F$46,L3,$Q$2:$Q$46,"Aprobada")>0,AND(Resumen!$B$15="La cursada aprobada",COUNTIFS($F$2:$F$46,L3,$Q$2:$Q$46,"Cursada aprobada")>0))),L3&" ","")&IF(NOT(OR(M3="",COUNTIF($F$2:$F$46,M3)=0,COUNTIFS($F$2:$F$46,M3,$Q$2:$Q$46,"Aprobada")>0,AND(Resumen!$B$15="La cursada aprobada",COUNTIFS($F$2:$F$46,M3,$Q$2:$Q$46,"Cursada aprobada")>0))),M3&" ","")&IF(NOT(OR(N3="",COUNTIF($F$2:$F$46,N3)=0,COUNTIFS($F$2:$F$46,N3,$Q$2:$Q$46,"Aprobada")>0,AND(Resumen!$B$15="La cursada aprobada",COUNTIFS($F$2:$F$46,N3,$Q$2:$Q$46,"Cursada aprobada")>0))),N3&" ","")&IF(NOT(OR(O3="",COUNTIF($F$2:$F$46,O3)=0,COUNTIFS($F$2:$F$46,O3,$Q$2:$Q$46,"Aprobada")>0,AND(Resumen!$B$15="La cursada aprobada",COUNTIFS($F$2:$F$46,O3,$Q$2:$Q$46,"Cursada aprobada")>0))),O3&" ","")&IF(NOT(OR(P3="",COUNTIF($F$2:$F$46,P3)=0,COUNTIFS($F$2:$F$46,P3,$Q$2:$Q$46,"Aprobada")>0,AND(Resumen!$B$15="La cursada aprobada",COUNTIFS($F$2:$F$46,P3,$Q$2:$Q$46,"Cursada aprobada")>0))),P3&" ","")) | T3: =IF(Q3="Cursada aprobada",IF(AND(OR(L3="",COUNTIF($F$2:$F$46,L3)=0,COUNTIFS($F$2:$F$46,L3,$Q$2:$Q$46,"Aprobada")>0),OR(M3="",COUNTIF($F$2:$F$46,M3)=0,COUNTIFS($F$2:$F$46,M3,$Q$2:$Q$46,"Aprobada")>0),OR(N3="",COUNTIF($F$2:$F$46,N3)=0,COUNTIFS($F$2:$F$46,N3,$Q$2:$Q$46,"Aprobada")>0),OR(O3="",COUNTIF($F$2:$F$46,O3)=0,COUNTIFS($F$2:$F$46,O3,$Q$2:$Q$46,"Aprobada")>0),OR(P3="",COUNTIF($F$2:$F$46,P3)=0,COUNTIFS($F$2:$F$46,P3,$Q$2:$Q$46,"Aprobada")>0)),"Sí","No"),"") | U3: =IF(Q3="Aprobada",TRIM(IF(NOT(OR(L3="",COUNTIF($F$2:$F$46,L3)=0,COUNTIFS($F$2:$F$46,L3,$Q$2:$Q$46,"Aprobada")>0)),L3&" ","")&IF(NOT(OR(M3="",COUNTIF($F$2:$F$46,M3)=0,COUNTIFS($F$2:$F$46,M3,$Q$2:$Q$46,"Aprobada")>0)),M3&" ","")&IF(NOT(OR(N3="",COUNTIF($F$2:$F$46,N3)=0,COUNTIFS($F$2:$F$46,N3,$Q$2:$Q$46,"Aprobada")>0)),N3&" ","")&IF(NOT(OR(O3="",COUNTIF($F$2:$F$46,O3)=0,COUNTIFS($F$2:$F$46,O3,$Q$2:$Q$46,"Aprobada")>0)),O3&" ","")&IF(NOT(OR(P3="",COUNTIF($F$2:$F$46,P3)=0,COUNTIFS($F$2:$F$46,P3,$Q$2:$Q$46,"Aprobada")>0)),P3&" ","")),IF(Q3="Cursada aprobada",TRIM(IF(NOT(OR(L3="",COUNTIF($F$2:$F$46,L3)=0,COUNTIFS($F$2:$F$46,L3,$Q$2:$Q$46,"Aprobada")>0,AND(Resumen!$B$15="La cursada aprobada",COUNTIFS($F$2:$F$46,L3,$Q$2:$Q$46,"Cursada aprobada")>0))),L3&" ","")&IF(NOT(OR(M3="",COUNTIF($F$2:$F$46,M3)=0,COUNTIFS($F$2:$F$46,M3,$Q$2:$Q$46,"Aprobada")>0,AND(Resumen!$B$15="La cursada aprobada",COUNTIFS($F$2:$F$46,M3,$Q$2:$Q$46,"Cursada aprobada")>0))),M3&" ","")&IF(NOT(OR(N3="",COUNTIF($F$2:$F$46,N3)=0,COUNTIFS($F$2:$F$46,N3,$Q$2:$Q$46,"Aprobada")>0,AND(Resumen!$B$15="La cursada aprobada",COUNTIFS($F$2:$F$46,N3,$Q$2:$Q$46,"Cursada aprobada")>0))),N3&" ","")&IF(NOT(OR(O3="",COUNTIF($F$2:$F$46,O3)=0,COUNTIFS($F$2:$F$46,O3,$Q$2:$Q$46,"Aprobada")>0,AND(Resumen!$B$15="La cursada aprobada",COUNTIFS($F$2:$F$46,O3,$Q$2:$Q$46,"Cursada aprobada")>0))),O3&" ","")&IF(NOT(OR(P3="",COUNTIF($F$2:$F$46,P3)=0,COUNTIFS($F$2:$F$46,P3,$Q$2:$Q$46,"Aprobada")>0,AND(Resumen!$B$15="La cursada aprobada",COUNTIFS($F$2:$F$46,P3,$Q$2:$Q$46,"Cursada aprobada")>0))),P3&" ","")),""))
A4: Ciclo básico | C4: 1 | D4: 1 | E4: MA | F4: 102 | G4: Matemática I | H4: I | I4: 6 | K4: 96 | Q4: No cursada | R4: =IF(Q4="Aprobada","Ya aprobada",IF(Q4="Cursada aprobada","Ya cursada",IF(AND(OR(L4="",COUNTIF($F$2:$F$46,L4)=0,COUNTIFS($F$2:$F$46,L4,$Q$2:$Q$46,"Aprobada")>0,AND(Resumen!$B$15="La cursada aprobada",COUNTIFS($F$2:$F$46,L4,$Q$2:$Q$46,"Cursada aprobada")>0)),OR(M4="",COUNTIF($F$2:$F$46,M4)=0,COUNTIFS($F$2:$F$46,M4,$Q$2:$Q$46,"Aprobada")>0,AND(Resumen!$B$15="La cursada aprobada",COUNTIFS($F$2:$F$46,M4,$Q$2:$Q$46,"Cursada aprobada")>0)),OR(N4="",COUNTIF($F$2:$F$46,N4)=0,COUNTIFS($F$2:$F$46,N4,$Q$2:$Q$46,"Aprobada")>0,AND(Resumen!$B$15="La cursada aprobada",COUNTIFS($F$2:$F$46,N4,$Q$2:$Q$46,"Cursada aprobada")>0)),OR(O4="",COUNTIF($F$2:$F$46,O4)=0,COUNTIFS($F$2:$F$46,O4,$Q$2:$Q$46,"Aprobada")>0,AND(Resumen!$B$15="La cursada aprobada",COUNTIFS($F$2:$F$46,O4,$Q$2:$Q$46,"Cursada aprobada")>0)),OR(P4="",COUNTIF($F$2:$F$46,P4)=0,COUNTIFS($F$2:$F$46,P4,$Q$2:$Q$46,"Aprobada")>0,AND(Resumen!$B$15="La cursada aprobada",COUNTIFS($F$2:$F$46,P4,$Q$2:$Q$46,"Cursada aprobada")>0))),"Sí","No"))) -> Sí | S4: =TRIM(IF(NOT(OR(L4="",COUNTIF($F$2:$F$46,L4)=0,COUNTIFS($F$2:$F$46,L4,$Q$2:$Q$46,"Aprobada")>0,AND(Resumen!$B$15="La cursada aprobada",COUNTIFS($F$2:$F$46,L4,$Q$2:$Q$46,"Cursada aprobada")>0))),L4&" ","")&IF(NOT(OR(M4="",COUNTIF($F$2:$F$46,M4)=0,COUNTIFS($F$2:$F$46,M4,$Q$2:$Q$46,"Aprobada")>0,AND(Resumen!$B$15="La cursada aprobada",COUNTIFS($F$2:$F$46,M4,$Q$2:$Q$46,"Cursada aprobada")>0))),M4&" ","")&IF(NOT(OR(N4="",COUNTIF($F$2:$F$46,N4)=0,COUNTIFS($F$2:$F$46,N4,$Q$2:$Q$46,"Aprobada")>0,AND(Resumen!$B$15="La cursada aprobada",COUNTIFS($F$2:$F$46,N4,$Q$2:$Q$46,"Cursada aprobada")>0))),N4&" ","")&IF(NOT(OR(O4="",COUNTIF($F$2:$F$46,O4)=0,COUNTIFS($F$2:$F$46,O4,$Q$2:$Q$46,"Aprobada")>0,AND(Resumen!$B$15="La cursada aprobada",COUNTIFS($F$2:$F$46,O4,$Q$2:$Q$46,"Cursada aprobada")>0))),O4&" ","")&IF(NOT(OR(P4="",COUNTIF($F$2:$F$46,P4)=0,COUNTIFS($F$2:$F$46,P4,$Q$2:$Q$46,"Aprobada")>0,AND(Resumen!$B$15="La cursada aprobada",COUNTIFS($F$2:$F$46,P4,$Q$2:$Q$46,"Cursada aprobada")>0))),P4&" ","")) | T4: =IF(Q4="Cursada aprobada",IF(AND(OR(L4="",COUNTIF($F$2:$F$46,L4)=0,COUNTIFS($F$2:$F$46,L4,$Q$2:$Q$46,"Aprobada")>0),OR(M4="",COUNTIF($F$2:$F$46,M4)=0,COUNTIFS($F$2:$F$46,M4,$Q$2:$Q$46,"Aprobada")>0),OR(N4="",COUNTIF($F$2:$F$46,N4)=0,COUNTIFS($F$2:$F$46,N4,$Q$2:$Q$46,"Aprobada")>0),OR(O4="",COUNTIF($F$2:$F$46,O4)=0,COUNTIFS($F$2:$F$46,O4,$Q$2:$Q$46,"Aprobada")>0),OR(P4="",COUNTIF($F$2:$F$46,P4)=0,COUNTIFS($F$2:$F$46,P4,$Q$2:$Q$46,"Aprobada")>0)),"Sí","No"),"") | U4: =IF(Q4="Aprobada",TRIM(IF(NOT(OR(L4="",COUNTIF($F$2:$F$46,L4)=0,COUNTIFS($F$2:$F$46,L4,$Q$2:$Q$46,"Aprobada")>0)),L4&" ","")&IF(NOT(OR(M4="",COUNTIF($F$2:$F$46,M4)=0,COUNTIFS($F$2:$F$46,M4,$Q$2:$Q$46,"Aprobada")>0)),M4&" ","")&IF(NOT(OR(N4="",COUNTIF($F$2:$F$46,N4)=0,COUNTIFS($F$2:$F$46,N4,$Q$2:$Q$46,"Aprobada")>0)),N4&" ","")&IF(NOT(OR(O4="",COUNTIF($F$2:$F$46,O4)=0,COUNTIFS($F$2:$F$46,O4,$Q$2:$Q$46,"Aprobada")>0)),O4&" ","")&IF(NOT(OR(P4="",COUNTIF($F$2:$F$46,P4)=0,COUNTIFS($F$2:$F$46,P4,$Q$2:$Q$46,"Aprobada")>0)),P4&" ","")),IF(Q4="Cursada aprobada",TRIM(IF(NOT(OR(L4="",COUNTIF($F$2:$F$46,L4)=0,COUNTIFS($F$2:$F$46,L4,$Q$2:$Q$46,"Aprobada")>0,AND(Resumen!$B$15="La cursada aprobada",COUNTIFS($F$2:$F$46,L4,$Q$2:$Q$46,"Cursada aprobada")>0))),L4&" ","")&IF(NOT(OR(M4="",COUNTIF($F$2:$F$46,M4)=0,COUNTIFS($F$2:$F$46,M4,$Q$2:$Q$46,"Aprobada")>0,AND(Resumen!$B$15="La cursada aprobada",COUNTIFS($F$2:$F$46,M4,$Q$2:$Q$46,"Cursada aprobada")>0))),M4&" ","")&IF(NOT(OR(N4="",COUNTIF($F$2:$F$46,N4)=0,COUNTIFS($F$2:$F$46,N4,$Q$2:$Q$46,"Aprobada")>0,AND(Resumen!$B$15="La cursada aprobada",COUNTIFS($F$2:$F$46,N4,$Q$2:$Q$46,"Cursada aprobada")>0))),N4&" ","")&IF(NOT(OR(O4="",COUNTIF($F$2:$F$46,O4)=0,COUNTIFS($F$2:$F$46,O4,$Q$2:$Q$46,"Aprobada")>0,AND(Resumen!$B$15="La cursada aprobada",COUNTIFS($F$2:$F$46,O4,$Q$2:$Q$46,"Cursada aprobada")>0))),O4&" ","")&IF(NOT(OR(P4="",COUNTIF($F$2:$F$46,P4)=0,COUNTIFS($F$2:$F$46,P4,$Q$2:$Q$46,"Aprobada")>0,AND(Resumen!$B$15="La cursada aprobada",COUNTIFS($F$2:$F$46,P4,$Q$2:$Q$46,"Cursada aprobada")>0))),P4&" ","")),""))
A5: Ciclo básico | C5: 1 | D5: 2 | E5: CO | F5: 103 | G5: Contabilidad I | H5: I | I5: 6 | K5: 96 | Q5: No cursada | R5: =IF(Q5="Aprobada","Ya aprobada",IF(Q5="Cursada aprobada","Ya cursada",IF(AND(OR(L5="",COUNTIF($F$2:$F$46,L5)=0,COUNTIFS($F$2:$F$46,L5,$Q$2:$Q$46,"Aprobada")>0,AND(Resumen!$B$15="La cursada aprobada",COUNTIFS($F$2:$F$46,L5,$Q$2:$Q$46,"Cursada aprobada")>0)),OR(M5="",COUNTIF($F$2:$F$46,M5)=0,COUNTIFS($F$2:$F$46,M5,$Q$2:$Q$46,"Aprobada")>0,AND(Resumen!$B$15="La cursada aprobada",COUNTIFS($F$2:$F$46,M5,$Q$2:$Q$46,"Cursada aprobada")>0)),OR(N5="",COUNTIF($F$2:$F$46,N5)=0,COUNTIFS($F$2:$F$46,N5,$Q$2:$Q$46,"Aprobada")>0,AND(Resumen!$B$15="La cursada aprobada",COUNTIFS($F$2:$F$46,N5,$Q$2:$Q$46,"Cursada aprobada")>0)),OR(O5="",COUNTIF($F$2:$F$46,O5)=0,COUNTIFS($F$2:$F$46,O5,$Q$2:$Q$46,"Aprobada")>0,AND(Resumen!$B$15="La cursada aprobada",COUNTIFS($F$2:$F$46,O5,$Q$2:$Q$46,"Cursada aprobada")>0)),OR(P5="",COUNTIF($F$2:$F$46,P5)=0,COUNTIFS($F$2:$F$46,P5,$Q$2:$Q$46,"Aprobada")>0,AND(Resumen!$B$15="La cursada aprobada",COUNTIFS($F$2:$F$46,P5,$Q$2:$Q$46,"Cursada aprobada")>0))),"Sí","No"))) -> Sí | S5: =TRIM(IF(NOT(OR(L5="",COUNTIF($F$2:$F$46,L5)=0,COUNTIFS($F$2:$F$46,L5,$Q$2:$Q$46,"Aprobada")>0,AND(Resumen!$B$15="La cursada aprobada",COUNTIFS($F$2:$F$46,L5,$Q$2:$Q$46,"Cursada aprobada")>0))),L5&" ","")&IF(NOT(OR(M5="",COUNTIF($F$2:$F$46,M5)=0,COUNTIFS($F$2:$F$46,M5,$Q$2:$Q$46,"Aprobada")>0,AND(Resumen!$B$15="La cursada aprobada",COUNTIFS($F$2:$F$46,M5,$Q$2:$Q$46,"Cursada aprobada")>0))),M5&" ","")&IF(NOT(OR(N5="",COUNTIF($F$2:$F$46,N5)=0,COUNTIFS($F$2:$F$46,N5,$Q$2:$Q$46,"Aprobada")>0,AND(Resumen!$B$15="La cursada aprobada",COUNTIFS($F$2:$F$46,N5,$Q$2:$Q$46,"Cursada aprobada")>0))),N5&" ","")&IF(NOT(OR(O5="",COUNTIF($F$2:$F$46,O5)=0,COUNTIFS($F$2:$F$46,O5,$Q$2:$Q$46,"Aprobada")>0,AND(Resumen!$B$15="La cursada aprobada",COUNTIFS($F$2:$F$46,O5,$Q$2:$Q$46,"Cursada aprobada")>0))),O5&" ","")&IF(NOT(OR(P5="",COUNTIF($F$2:$F$46,P5)=0,COUNTIFS($F$2:$F$46,P5,$Q$2:$Q$46,"Aprobada")>0,AND(Resumen!$B$15="La cursada aprobada",COUNTIFS($F$2:$F$46,P5,$Q$2:$Q$46,"Cursada aprobada")>0))),P5&" ","")) | T5: =IF(Q5="Cursada aprobada",IF(AND(OR(L5="",COUNTIF($F$2:$F$46,L5)=0,COUNTIFS($F$2:$F$46,L5,$Q$2:$Q$46,"Aprobada")>0),OR(M5="",COUNTIF($F$2:$F$46,M5)=0,COUNTIFS($F$2:$F$46,M5,$Q$2:$Q$46,"Aprobada")>0),OR(N5="",COUNTIF($F$2:$F$46,N5)=0,COUNTIFS($F$2:$F$46,N5,$Q$2:$Q$46,"Aprobada")>0),OR(O5="",COUNTIF($F$2:$F$46,O5)=0,COUNTIFS($F$2:$F$46,O5,$Q$2:$Q$46,"Aprobada")>0),OR(P5="",COUNTIF($F$2:$F$46,P5)=0,COUNTIFS($F$2:$F$46,P5,$Q$2:$Q$46,"Aprobada")>0)),"Sí","No"),"") | U5: =IF(Q5="Aprobada",TRIM(IF(NOT(OR(L5="",COUNTIF($F$2:$F$46,L5)=0,COUNTIFS($F$2:$F$46,L5,$Q$2:$Q$46,"Aprobada")>0)),L5&" ","")&IF(NOT(OR(M5="",COUNTIF($F$2:$F$46,M5)=0,COUNTIFS($F$2:$F$46,M5,$Q$2:$Q$46,"Aprobada")>0)),M5&" ","")&IF(NOT(OR(N5="",COUNTIF($F$2:$F$46,N5)=0,COUNTIFS($F$2:$F$46,N5,$Q$2:$Q$46,"Aprobada")>0)),N5&" ","")&IF(NOT(OR(O5="",COUNTIF($F$2:$F$46,O5)=0,COUNTIFS($F$2:$F$46,O5,$Q$2:$Q$46,"Aprobada")>0)),O5&" ","")&IF(NOT(OR(P5="",COUNTIF($F$2:$F$46,P5)=0,COUNTIFS($F$2:$F$46,P5,$Q$2:$Q$46,"Aprobada")>0)),P5&" ","")),IF(Q5="Cursada aprobada",TRIM(IF(NOT(OR(L5="",COUNTIF($F$2:$F$46,L5)=0,COUNTIFS($F$2:$F$46,L5,$Q$2:$Q$46,"Aprobada")>0,AND(Resumen!$B$15="La cursada aprobada",COUNTIFS($F$2:$F$46,L5,$Q$2:$Q$46,"Cursada aprobada")>0))),L5&" ","")&IF(NOT(OR(M5="",COUNTIF($F$2:$F$46,M5)=0,COUNTIFS($F$2:$F$46,M5,$Q$2:$Q$46,"Aprobada")>0,AND(Resumen!$B$15="La cursada aprobada",COUNTIFS($F$2:$F$46,M5,$Q$2:$Q$46,"Cursada aprobada")>0))),M5&" ","")&IF(NOT(OR(N5="",COUNTIF($F$2:$F$46,N5)=0,COUNTIFS($F$2:$F$46,N5,$Q$2:$Q$46,"Aprobada")>0,AND(Resumen!$B$15="La cursada aprobada",COUNTIFS($F$2:$F$46,N5,$Q$2:$Q$46,"Cursada aprobada")>0))),N5&" ","")&IF(NOT(OR(O5="",COUNTIF($F$2:$F$46,O5)=0,COUNTIFS($F$2:$F$46,O5,$Q$2:$Q$46,"Aprobada")>0,AND(Resumen!$B$15="La cursada aprobada",COUNTIFS($F$2:$F$46,O5,$Q$2:$Q$46,"Cursada aprobada")>0))),O5&" ","")&IF(NOT(OR(P5="",COUNTIF($F$2:$F$46,P5)=0,COUNTIFS($F$2:$F$46,P5,$Q$2:$Q$46,"Aprobada")>0,AND(Resumen!$B$15="La cursada aprobada",COUNTIFS($F$2:$F$46,P5,$Q$2:$Q$46,"Cursada aprobada")>0))),P5&" ","")),""))
A6: Ciclo básico | C6: 1 | D6: 2 | E6: CS | F6: 180 | G6: Historia Económica y Social I | H6: II | I6: 4 | K6: 64 | Q6: No cursada | R6: =IF(Q6="Aprobada","Ya aprobada",IF(Q6="Cursada aprobada","Ya cursada",IF(AND(OR(L6="",COUNTIF($F$2:$F$46,L6)=0,COUNTIFS($F$2:$F$46,L6,$Q$2:$Q$46,"Aprobada")>0,AND(Resumen!$B$15="La cursada aprobada",COUNTIFS($F$2:$F$46,L6,$Q$2:$Q$46,"Cursada aprobada")>0)),OR(M6="",COUNTIF($F$2:$F$46,M6)=0,COUNTIFS($F$2:$F$46,M6,$Q$2:$Q$46,"Aprobada")>0,AND(Resumen!$B$15="La cursada aprobada",COUNTIFS($F$2:$F$46,M6,$Q$2:$Q$46,"Cursada aprobada")>0)),OR(N6="",COUNTIF($F$2:$F$46,N6)=0,COUNTIFS($F$2:$F$46,N6,$Q$2:$Q$46,"Aprobada")>0,AND(Resumen!$B$15="La cursada aprobada",COUNTIFS($F$2:$F$46,N6,$Q$2:$Q$46,"Cursada aprobada")>0)),OR(O6="",COUNTIF($F$2:$F$46,O6)=0,COUNTIFS($F$2:$F$46,O6,$Q$2:$Q$46,"Aprobada")>0,AND(Resumen!$B$15="La cursada aprobada",COUNTIFS($F$2:$F$46,O6,$Q$2:$Q$46,"Cursada aprobada")>0)),OR(P6="",COUNTIF($F$2:$F$46,P6)=0,COUNTIFS($F$2:$F$46,P6,$Q$2:$Q$46,"Aprobada")>0,AND(Resumen!$B$15="La cursada aprobada",COUNTIFS($F$2:$F$46,P6,$Q$2:$Q$46,"Cursada aprobada")>0))),"Sí","No"))) -> Sí | S6: =TRIM(IF(NOT(OR(L6="",COUNTIF($F$2:$F$46,L6)=0,COUNTIFS($F$2:$F$46,L6,$Q$2:$Q$46,"Aprobada")>0,AND(Resumen!$B$15="La cursada aprobada",COUNTIFS($F$2:$F$46,L6,$Q$2:$Q$46,"Cursada aprobada")>0))),L6&" ","")&IF(NOT(OR(M6="",COUNTIF($F$2:$F$46,M6)=0,COUNTIFS($F$2:$F$46,M6,$Q$2:$Q$46,"Aprobada")>0,AND(Resumen!$B$15="La cursada aprobada",COUNTIFS($F$2:$F$46,M6,$Q$2:$Q$46,"Cursada aprobada")>0))),M6&" ","")&IF(NOT(OR(N6="",COUNTIF($F$2:$F$46,N6)=0,COUNTIFS($F$2:$F$46,N6,$Q$2:$Q$46,"Aprobada")>0,AND(Resumen!$B$15="La cursada aprobada",COUNTIFS($F$2:$F$46,N6,$Q$2:$Q$46,"Cursada aprobada")>0))),N6&" ","")&IF(NOT(OR(O6="",COUNTIF($F$2:$F$46,O6)=0,COUNTIFS($F$2:$F$46,O6,$Q$2:$Q$46,"Aprobada")>0,AND(Resumen!$B$15="La cursada aprobada",COUNTIFS($F$2:$F$46,O6,$Q$2:$Q$46,"Cursada aprobada")>0))),O6&" ","")&IF(NOT(OR(P6="",COUNTIF($F$2:$F$46,P6)=0,COUNTIFS($F$2:$F$46,P6,$Q$2:$Q$46,"Aprobada")>0,AND(Resumen!$B$15="La cursada aprobada",COUNTIFS($F$2:$F$46,P6,$Q$2:$Q$46,"Cursada aprobada")>0))),P6&" ","")) | T6: =IF(Q6="Cursada aprobada",IF(AND(OR(L6="",COUNTIF($F$2:$F$46,L6)=0,COUNTIFS($F$2:$F$46,L6,$Q$2:$Q$46,"Aprobada")>0),OR(M6="",COUNTIF($F$2:$F$46,M6)=0,COUNTIFS($F$2:$F$46,M6,$Q$2:$Q$46,"Aprobada")>0),OR(N6="",COUNTIF($F$2:$F$46,N6)=0,COUNTIFS($F$2:$F$46,N6,$Q$2:$Q$46,"Aprobada")>0),OR(O6="",COUNTIF($F$2:$F$46,O6)=0,COUNTIFS($F$2:$F$46,O6,$Q$2:$Q$46,"Aprobada")>0),OR(P6="",COUNTIF($F$2:$F$46,P6)=0,COUNTIFS($F$2:$F$46,P6,$Q$2:$Q$46,"Aprobada")>0)),"Sí","No"),"") | U6: =IF(Q6="Aprobada",TRIM(IF(NOT(OR(L6="",COUNTIF($F$2:$F$46,L6)=0,COUNTIFS($F$2:$F$46,L6,$Q$2:$Q$46,"Aprobada")>0)),L6&" ","")&IF(NOT(OR(M6="",COUNTIF($F$2:$F$46,M6)=0,COUNTIFS($F$2:$F$46,M6,$Q$2:$Q$46,"Aprobada")>0)),M6&" ","")&IF(NOT(OR(N6="",COUNTIF($F$2:$F$46,N6)=0,COUNTIFS($F$2:$F$46,N6,$Q$2:$Q$46,"Aprobada")>0)),N6&" ","")&IF(NOT(OR(O6="",COUNTIF($F$2:$F$46,O6)=0,COUNTIFS($F$2:$F$46,O6,$Q$2:$Q$46,"Aprobada")>0)),O6&" ","")&IF(NOT(OR(P6="",COUNTIF($F$2:$F$46,P6)=0,COUNTIFS($F$2:$F$46,P6,$Q$2:$Q$46,"Aprobada")>0)),P6&" ","")),IF(Q6="Cursada aprobada",TRIM(IF(NOT(OR(L6="",COUNTIF($F$2:$F$46,L6)=0,COUNTIFS($F$2:$F$46,L6,$Q$2:$Q$46,"Aprobada")>0,AND(Resumen!$B$15="La cursada aprobada",COUNTIFS($F$2:$F$46,L6,$Q$2:$Q$46,"Cursada aprobada")>0))),L6&" ","")&IF(NOT(OR(M6="",COUNTIF($F$2:$F$46,M6)=0,COUNTIFS($F$2:$F$46,M6,$Q$2:$Q$46,"Aprobada")>0,AND(Resumen!$B$15="La cursada aprobada",COUNTIFS($F$2:$F$46,M6,$Q$2:$Q$46,"Cursada aprobada")>0))),M6&" ","")&IF(NOT(OR(N6="",COUNTIF($F$2:$F$46,N6)=0,COUNTIFS($F$2:$F$46,N6,$Q$2:$Q$46,"Aprobada")>0,AND(Resumen!$B$15="La cursada aprobada",COUNTIFS($F$2:$F$46,N6,$Q$2:$Q$46,"Cursada aprobada")>0))),N6&" ","")&IF(NOT(OR(O6="",COUNTIF($F$2:$F$46,O6)=0,COUNTIFS($F$2:$F$46,O6,$Q$2:$Q$46,"Aprobada")>0,AND(Resumen!$B$15="La cursada aprobada",COUNTIFS($F$2:$F$46,O6,$Q$2:$Q$46,"Cursada aprobada")>0))),O6&" ","")&IF(NOT(OR(P6="",COUNTIF($F$2:$F$46,P6)=0,COUNTIFS($F$2:$F$46,P6,$Q$2:$Q$46,"Aprobada")>0,AND(Resumen!$B$15="La cursada aprobada",COUNTIFS($F$2:$F$46,P6,$Q$2:$Q$46,"Cursada aprobada")>0))),P6&" ","")),""))
A7: Ciclo básico | C7: 1 | D7: 2 | E7: CS | F7: 205 | G7: Sociología | H7: II | I7: 4 | K7: 64 | Q7: No cursada | R7: =IF(Q7="Aprobada","Ya aprobada",IF(Q7="Cursada aprobada","Ya cursada",IF(AND(OR(L7="",COUNTIF($F$2:$F$46,L7)=0,COUNTIFS($F$2:$F$46,L7,$Q$2:$Q$46,"Aprobada")>0,AND(Resumen!$B$15="La cursada aprobada",COUNTIFS($F$2:$F$46,L7,$Q$2:$Q$46,"Cursada aprobada")>0)),OR(M7="",COUNTIF($F$2:$F$46,M7)=0,COUNTIFS($F$2:$F$46,M7,$Q$2:$Q$46,"Aprobada")>0,AND(Resumen!$B$15="La cursada aprobada",COUNTIFS($F$2:$F$46,M7,$Q$2:$Q$46,"Cursada aprobada")>0)),OR(N7="",COUNTIF($F$2:$F$46,N7)=0,COUNTIFS($F$2:$F$46,N7,$Q$2:$Q$46,"Aprobada")>0,AND(Resumen!$B$15="La cursada aprobada",COUNTIFS($F$2:$F$46,N7,$Q$2:$Q$46,"Cursada aprobada")>0)),OR(O7="",COUNTIF($F$2:$F$46,O7)=0,COUNTIFS($F$2:$F$46,O7,$Q$2:$Q$46,"Aprobada")>0,AND(Resumen!$B$15="La cursada aprobada",COUNTIFS($F$2:$F$46,O7,$Q$2:$Q$46,"Cursada aprobada")>0)),OR(P7="",COUNTIF($F$2:$F$46,P7)=0,COUNTIFS($F$2:$F$46,P7,$Q$2:$Q$46,"Aprobada")>0,AND(Resumen!$B$15="La cursada aprobada",COUNTIFS($F$2:$F$46,P7,$Q$2:$Q$46,"Cursada aprobada")>0))),"Sí","No"))) -> Sí | S7: =TRIM(IF(NOT(OR(L7="",COUNTIF($F$2:$F$46,L7)=0,COUNTIFS($F$2:$F$46,L7,$Q$2:$Q$46,"Aprobada")>0,AND(Resumen!$B$15="La cursada aprobada",COUNTIFS($F$2:$F$46,L7,$Q$2:$Q$46,"Cursada aprobada")>0))),L7&" ","")&IF(NOT(OR(M7="",COUNTIF($F$2:$F$46,M7)=0,COUNTIFS($F$2:$F$46,M7,$Q$2:$Q$46,"Aprobada")>0,AND(Resumen!$B$15="La cursada aprobada",COUNTIFS($F$2:$F$46,M7,$Q$2:$Q$46,"Cursada aprobada")>0))),M7&" ","")&IF(NOT(OR(N7="",COUNTIF($F$2:$F$46,N7)=0,COUNTIFS($F$2:$F$46,N7,$Q$2:$Q$46,"Aprobada")>0,AND(Resumen!$B$15="La cursada aprobada",COUNTIFS($F$2:$F$46,N7,$Q$2:$Q$46,"Cursada aprobada")>0))),N7&" ","")&IF(NOT(OR(O7="",COUNTIF($F$2:$F$46,O7)=0,COUNTIFS($F$2:$F$46,O7,$Q$2:$Q$46,"Aprobada")>0,AND(Resumen!$B$15="La cursada aprobada",COUNTIFS($F$2:$F$46,O7,$Q$2:$Q$46,"Cursada aprobada")>0))),O7&" ","")&IF(NOT(OR(P7="",COUNTIF($F$2:$F$46,P7)=0,COUNTIFS($F$2:$F$46,P7,$Q$2:$Q$46,"Aprobada")>0,AND(Resumen!$B$15="La cursada aprobada",COUNTIFS($F$2:$F$46,P7,$Q$2:$Q$46,"Cursada aprobada")>0))),P7&" ","")) | T7: =IF(Q7="Cursada aprobada",IF(AND(OR(L7="",COUNTIF($F$2:$F$46,L7)=0,COUNTIFS($F$2:$F$46,L7,$Q$2:$Q$46,"Aprobada")>0),OR(M7="",COUNTIF($F$2:$F$46,M7)=0,COUNTIFS($F$2:$F$46,M7,$Q$2:$Q$46,"Aprobada")>0),OR(N7="",COUNTIF($F$2:$F$46,N7)=0,COUNTIFS($F$2:$F$46,N7,$Q$2:$Q$46,"Aprobada")>0),OR(O7="",COUNTIF($F$2:$F$46,O7)=0,COUNTIFS($F$2:$F$46,O7,$Q$2:$Q$46,"Aprobada")>0),OR(P7="",COUNTIF($F$2:$F$46,P7)=0,COUNTIFS($F$2:$F$46,P7,$Q$2:$Q$46,"Aprobada")>0)),"Sí","No"),"") | U7: =IF(Q7="Aprobada",TRIM(IF(NOT(OR(L7="",COUNTIF($F$2:$F$46,L7)=0,COUNTIFS($F$2:$F$46,L7,$Q$2:$Q$46,"Aprobada")>0)),L7&" ","")&IF(NOT(OR(M7="",COUNTIF($F$2:$F$46,M7)=0,COUNTIFS($F$2:$F$46,M7,$Q$2:$Q$46,"Aprobada")>0)),M7&" ","")&IF(NOT(OR(N7="",COUNTIF($F$2:$F$46,N7)=0,COUNTIFS($F$2:$F$46,N7,$Q$2:$Q$46,"Aprobada")>0)),N7&" ","")&IF(NOT(OR(O7="",COUNTIF($F$2:$F$46,O7)=0,COUNTIFS($F$2:$F$46,O7,$Q$2:$Q$46,"Aprobada")>0)),O7&" ","")&IF(NOT(OR(P7="",COUNTIF($F$2:$F$46,P7)=0,COUNTIFS($F$2:$F$46,P7,$Q$2:$Q$46,"Aprobada")>0)),P7&" ","")),IF(Q7="Cursada aprobada",TRIM(IF(NOT(OR(L7="",COUNTIF($F$2:$F$46,L7)=0,COUNTIFS($F$2:$F$46,L7,$Q$2:$Q$46,"Aprobada")>0,AND(Resumen!$B$15="La cursada aprobada",COUNTIFS($F$2:$F$46,L7,$Q$2:$Q$46,"Cursada aprobada")>0))),L7&" ","")&IF(NOT(OR(M7="",COUNTIF($F$2:$F$46,M7)=0,COUNTIFS($F$2:$F$46,M7,$Q$2:$Q$46,"Aprobada")>0,AND(Resumen!$B$15="La cursada aprobada",COUNTIFS($F$2:$F$46,M7,$Q$2:$Q$46,"Cursada aprobada")>0))),M7&" ","")&IF(NOT(OR(N7="",COUNTIF($F$2:$F$46,N7)=0,COUNTIFS($F$2:$F$46,N7,$Q$2:$Q$46,"Aprobada")>0,AND(Resumen!$B$15="La cursada aprobada",COUNTIFS($F$2:$F$46,N7,$Q$2:$Q$46,"Cursada aprobada")>0))),N7&" ","")&IF(NOT(OR(O7="",COUNTIF($F$2:$F$46,O7)=0,COUNTIFS($F$2:$F$46,O7,$Q$2:$Q$46,"Aprobada")>0,AND(Resumen!$B$15="La cursada aprobada",COUNTIFS($F$2:$F$46,O7,$Q$2:$Q$46,"Cursada aprobada")>0))),O7&" ","")&IF(NOT(OR(P7="",COUNTIF($F$2:$F$46,P7)=0,COUNTIFS($F$2:$F$46,P7,$Q$2:$Q$46,"Aprobada")>0,AND(Resumen!$B$15="La cursada aprobada",COUNTIFS($F$2:$F$46,P7,$Q$2:$Q$46,"Cursada aprobada")>0))),P7&" ","")),""))
A8: Ciclo básico | C8: 1 | D8: 2 | E8: MA | F8: 209 | G8: Matemática II | H8: I | I8: 5 | K8: 80 | L8: 102 | Q8: No cursada | R8: =IF(Q8="Aprobada","Ya aprobada",IF(Q8="Cursada aprobada","Ya cursada",IF(AND(OR(L8="",COUNTIF($F$2:$F$46,L8)=0,COUNTIFS($F$2:$F$46,L8,$Q$2:$Q$46,"Aprobada")>0,AND(Resumen!$B$15="La cursada aprobada",COUNTIFS($F$2:$F$46,L8,$Q$2:$Q$46,"Cursada aprobada")>0)),OR(M8="",COUNTIF($F$2:$F$46,M8)=0,COUNTIFS($F$2:$F$46,M8,$Q$2:$Q$46,"Aprobada")>0,AND(Resumen!$B$15="La cursada aprobada",COUNTIFS($F$2:$F$46,M8,$Q$2:$Q$46,"Cursada aprobada")>0)),OR(N8="",COUNTIF($F$2:$F$46,N8)=0,COUNTIFS($F$2:$F$46,N8,$Q$2:$Q$46,"Aprobada")>0,AND(Resumen!$B$15="La cursada aprobada",COUNTIFS($F$2:$F$46,N8,$Q$2:$Q$46,"Cursada aprobada")>0)),OR(O8="",COUNTIF($F$2:$F$46,O8)=0,COUNTIFS($F$2:$F$46,O8,$Q$2:$Q$46,"Aprobada")>0,AND(Resumen!$B$15="La cursada aprobada",COUNTIFS($F$2:$F$46,O8,$Q$2:$Q$46,"Cursada aprobada")>0)),OR(P8="",COUNTIF($F$2:$F$46,P8)=0,COUNTIFS($F$2:$F$46,P8,$Q$2:$Q$46,"Aprobada")>0,AND(Resumen!$B$15="La cursada aprobada",COUNTIFS($F$2:$F$46,P8,$Q$2:$Q$46,"Cursada aprobada")>0))),"Sí","No"))) -> No | S8: =TRIM(IF(NOT(OR(L8="",COUNTIF($F$2:$F$46,L8)=0,COUNTIFS($F$2:$F$46,L8,$Q$2:$Q$46,"Aprobada")>0,AND(Resumen!$B$15="La cursada aprobada",COUNTIFS($F$2:$F$46,L8,$Q$2:$Q$46,"Cursada aprobada")>0))),L8&" ","")&IF(NOT(OR(M8="",COUNTIF($F$2:$F$46,M8)=0,COUNTIFS($F$2:$F$46,M8,$Q$2:$Q$46,"Aprobada")>0,AND(Resumen!$B$15="La cursada aprobada",COUNTIFS($F$2:$F$46,M8,$Q$2:$Q$46,"Cursada aprobada")>0))),M8&" ","")&IF(NOT(OR(N8="",COUNTIF($F$2:$F$46,N8)=0,COUNTIFS($F$2:$F$46,N8,$Q$2:$Q$46,"Aprobada")>0,AND(Resumen!$B$15="La cursada aprobada",COUNTIFS($F$2:$F$46,N8,$Q$2:$Q$46,"Cursada aprobada")>0))),N8&" ","")&IF(NOT(OR(O8="",COUNTIF($F$2:$F$46,O8)=0,COUNTIFS($F$2:$F$46,O8,$Q$2:$Q$46,"Aprobada")>0,AND(Resumen!$B$15="La cursada aprobada",COUNTIFS($F$2:$F$46,O8,$Q$2:$Q$46,"Cursada aprobada")>0))),O8&" ","")&IF(NOT(OR(P8="",COUNTIF($F$2:$F$46,P8)=0,COUNTIFS($F$2:$F$46,P8,$Q$2:$Q$46,"Aprobada")>0,AND(Resumen!$B$15="La cursada aprobada",COUNTIFS($F$2:$F$46,P8,$Q$2:$Q$46,"Cursada aprobada")>0))),P8&" ","")) -> 102 | T8: =IF(Q8="Cursada aprobada",IF(AND(OR(L8="",COUNTIF($F$2:$F$46,L8)=0,COUNTIFS($F$2:$F$46,L8,$Q$2:$Q$46,"Aprobada")>0),OR(M8="",COUNTIF($F$2:$F$46,M8)=0,COUNTIFS($F$2:$F$46,M8,$Q$2:$Q$46,"Aprobada")>0),OR(N8="",COUNTIF($F$2:$F$46,N8)=0,COUNTIFS($F$2:$F$46,N8,$Q$2:$Q$46,"Aprobada")>0),OR(O8="",COUNTIF($F$2:$F$46,O8)=0,COUNTIFS($F$2:$F$46,O8,$Q$2:$Q$46,"Aprobada")>0),OR(P8="",COUNTIF($F$2:$F$46,P8)=0,COUNTIFS($F$2:$F$46,P8,$Q$2:$Q$46,"Aprobada")>0)),"Sí","No"),"") | U8: =IF(Q8="Aprobada",TRIM(IF(NOT(OR(L8="",COUNTIF($F$2:$F$46,L8)=0,COUNTIFS($F$2:$F$46,L8,$Q$2:$Q$46,"Aprobada")>0)),L8&" ","")&IF(NOT(OR(M8="",COUNTIF($F$2:$F$46,M8)=0,COUNTIFS($F$2:$F$46,M8,$Q$2:$Q$46,"Aprobada")>0)),M8&" ","")&IF(NOT(OR(N8="",COUNTIF($F$2:$F$46,N8)=0,COUNTIFS($F$2:$F$46,N8,$Q$2:$Q$46,"Aprobada")>0)),N8&" ","")&IF(NOT(OR(O8="",COUNTIF($F$2:$F$46,O8)=0,COUNTIFS($F$2:$F$46,O8,$Q$2:$Q$46,"Aprobada")>0)),O8&" ","")&IF(NOT(OR(P8="",COUNTIF($F$2:$F$46,P8)=0,COUNTIFS($F$2:$F$46,P8,$Q$2:$Q$46,"Aprobada")>0)),P8&" ","")),IF(Q8="Cursada aprobada",TRIM(IF(NOT(OR(L8="",COUNTIF($F$2:$F$46,L8)=0,COUNTIFS($F$2:$F$46,L8,$Q$2:$Q$46,"Aprobada")>0,AND(Resumen!$B$15="La cursada aprobada",COUNTIFS($F$2:$F$46,L8,$Q$2:$Q$46,"Cursada aprobada")>0))),L8&" ","")&IF(NOT(OR(M8="",COUNTIF($F$2:$F$46,M8)=0,COUNTIFS($F$2:$F$46,M8,$Q$2:$Q$46,"Aprobada")>0,AND(Resumen!$B$15="La cursada aprobada",COUNTIFS($F$2:$F$46,M8,$Q$2:$Q$46,"Cursada aprobada")>0))),M8&" ","")&IF(NOT(OR(N8="",COUNTIF($F$2:$F$46,N8)=0,COUNTIFS($F$2:$F$46,N8,$Q$2:$Q$46,"Aprobada")>0,AND(Resumen!$B$15="La cursada aprobada",COUNTIFS($F$2:$F$46,N8,$Q$2:$Q$46,"Cursada aprobada")>0))),N8&" ","")&IF(NOT(OR(O8="",COUNTIF($F$2:$F$46,O8)=0,COUNTIFS($F$2:$F$46,O8,$Q$2:$Q$46,"Aprobada")>0,AND(Resumen!$B$15="La cursada aprobada",COUNTIFS($F$2:$F$46,O8,$Q$2:$Q$46,"Cursada aprobada")>0))),O8&" ","")&IF(NOT(OR(P8="",COUNTIF($F$2:$F$46,P8)=0,COUNTIFS($F$2:$F$46,P8,$Q$2:$Q$46,"Aprobada")>0,AND(Resumen!$B$15="La cursada aprobada",COUNTIFS($F$2:$F$46,P8,$Q$2:$Q$46,"Cursada aprobada")>0))),P8&" ","")),""))
A9: Ciclo básico | C9: 2 | D9: 1 | E9: EC | F9: 314 | G9: Macroeconomía I | H9: I | I9: 6 | K9: 96 | L9: 101 | M9: 209 | Q9: No cursada | R9: =IF(Q9="Aprobada","Ya aprobada",IF(Q9="Cursada aprobada","Ya cursada",IF(AND(OR(L9="",COUNTIF($F$2:$F$46,L9)=0,COUNTIFS($F$2:$F$46,L9,$Q$2:$Q$46,"Aprobada")>0,AND(Resumen!$B$15="La cursada aprobada",COUNTIFS($F$2:$F$46,L9,$Q$2:$Q$46,"Cursada aprobada")>0)),OR(M9="",COUNTIF($F$2:$F$46,M9)=0,COUNTIFS($F$2:$F$46,M9,$Q$2:$Q$46,"Aprobada")>0,AND(Resumen!$B$15="La cursada aprobada",COUNTIFS($F$2:$F$46,M9,$Q$2:$Q$46,"Cursada aprobada")>0)),OR(N9="",COUNTIF($F$2:$F$46,N9)=0,COUNTIFS($F$2:$F$46,N9,$Q$2:$Q$46,"Aprobada")>0,AND(Resumen!$B$15="La cursada aprobada",COUNTIFS($F$2:$F$46,N9,$Q$2:$Q$46,"Cursada aprobada")>0)),OR(O9="",COUNTIF($F$2:$F$46,O9)=0,COUNTIFS($F$2:$F$46,O9,$Q$2:$Q$46,"Aprobada")>0,AND(Resumen!$B$15="La cursada aprobada",COUNTIFS($F$2:$F$46,O9,$Q$2:$Q$46,"Cursada aprobada")>0)),OR(P9="",COUNTIF($F$2:$F$46,P9)=0,COUNTIFS($F$2:$F$46,P9,$Q$2:$Q$46,"Aprobada")>0,AND(Resumen!$B$15="La cursada aprobada",COUNTIFS($F$2:$F$46,P9,$Q$2:$Q$46,"Cursada aprobada")>0))),"Sí","No"))) -> No | S9: =TRIM(IF(NOT(OR(L9="",COUNTIF($F$2:$F$46,L9)=0,COUNTIFS($F$2:$F$46,L9,$Q$2:$Q$46,"Aprobada")>0,AND(Resumen!$B$15="La cursada aprobada",COUNTIFS($F$2:$F$46,L9,$Q$2:$Q$46,"Cursada aprobada")>0))),L9&" ","")&IF(NOT(OR(M9="",COUNTIF($F$2:$F$46,M9)=0,COUNTIFS($F$2:$F$46,M9,$Q$2:$Q$46,"Aprobada")>0,AND(Resumen!$B$15="La cursada aprobada",COUNTIFS($F$2:$F$46,M9,$Q$2:$Q$46,"Cursada aprobada")>0))),M9&" ","")&IF(NOT(OR(N9="",COUNTIF($F$2:$F$46,N9)=0,COUNTIFS($F$2:$F$46,N9,$Q$2:$Q$46,"Aprobada")>0,AND(Resumen!$B$15="La cursada aprobada",COUNTIFS($F$2:$F$46,N9,$Q$2:$Q$46,"Cursada aprobada")>0))),N9&" ","")&IF(NOT(OR(O9="",COUNTIF($F$2:$F$46,O9)=0,COUNTIFS($F$2:$F$46,O9,$Q$2:$Q$46,"Aprobada")>0,AND(Resumen!$B$15="La cursada aprobada",COUNTIFS($F$2:$F$46,O9,$Q$2:$Q$46,"Cursada aprobada")>0))),O9&" ","")&IF(NOT(OR(P9="",COUNTIF($F$2:$F$46,P9)=0,COUNTIFS($F$2:$F$46,P9,$Q$2:$Q$46,"Aprobada")>0,AND(Resumen!$B$15="La cursada aprobada",COUNTIFS($F$2:$F$46,P9,$Q$2:$Q$46,"Cursada aprobada")>0))),P9&" ","")) -> 101 209 | T9: =IF(Q9="Cursada aprobada",IF(AND(OR(L9="",COUNTIF($F$2:$F$46,L9)=0,COUNTIFS($F$2:$F$46,L9,$Q$2:$Q$46,"Aprobada")>0),OR(M9="",COUNTIF($F$2:$F$46,M9)=0,COUNTIFS($F$2:$F$46,M9,$Q$2:$Q$46,"Aprobada")>0),OR(N9="",COUNTIF($F$2:$F$46,N9)=0,COUNTIFS($F$2:$F$46,N9,$Q$2:$Q$46,"Aprobada")>0),OR(O9="",COUNTIF($F$2:$F$46,O9)=0,COUNTIFS($F$2:$F$46,O9,$Q$2:$Q$46,"Aprobada")>0),OR(P9="",COUNTIF($F$2:$F$46,P9)=0,COUNTIFS($F$2:$F$46,P9,$Q$2:$Q$46,"Aprobada")>0)),"Sí","No"),"") | U9: =IF(Q9="Aprobada",TRIM(IF(NOT(OR(L9="",COUNTIF($F$2:$F$46,L9)=0,COUNTIFS($F$2:$F$46,L9,$Q$2:$Q$46,"Aprobada")>0)),L9&" ","")&IF(NOT(OR(M9="",COUNTIF($F$2:$F$46,M9)=0,COUNTIFS($F$2:$F$46,M9,$Q$2:$Q$46,"Aprobada")>0)),M9&" ","")&IF(NOT(OR(N9="",COUNTIF($F$2:$F$46,N9)=0,COUNTIFS($F$2:$F$46,N9,$Q$2:$Q$46,"Aprobada")>0)),N9&" ","")&IF(NOT(OR(O9="",COUNTIF($F$2:$F$46,O9)=0,COUNTIFS($F$2:$F$46,O9,$Q$2:$Q$46,"Aprobada")>0)),O9&" ","")&IF(NOT(OR(P9="",COUNTIF($F$2:$F$46,P9)=0,COUNTIFS($F$2:$F$46,P9,$Q$2:$Q$46,"Aprobada")>0)),P9&" ","")),IF(Q9="Cursada aprobada",TRIM(IF(NOT(OR(L9="",COUNTIF($F$2:$F$46,L9)=0,COUNTIFS($F$2:$F$46,L9,$Q$2:$Q$46,"Aprobada")>0,AND(Resumen!$B$15="La cursada aprobada",COUNTIFS($F$2:$F$46,L9,$Q$2:$Q$46,"Cursada aprobada")>0))),L9&" ","")&IF(NOT(OR(M9="",COUNTIF($F$2:$F$46,M9)=0,COUNTIFS($F$2:$F$46,M9,$Q$2:$Q$46,"Aprobada")>0,AND(Resumen!$B$15="La cursada aprobada",COUNTIFS($F$2:$F$46,M9,$Q$2:$Q$46,"Cursada aprobada")>0))),M9&" ","")&IF(NOT(OR(N9="",COUNTIF($F$2:$F$46,N9)=0,COUNTIFS($F$2:$F$46,N9,$Q$2:$Q$46,"Aprobada")>0,AND(Resumen!$B$15="La cursada aprobada",COUNTIFS($F$2:$F$46,N9,$Q$2:$Q$46,"Cursada aprobada")>0))),N9&" ","")&IF(NOT(OR(O9="",COUNTIF($F$2:$F$46,O9)=0,COUNTIFS($F$2:$F$46,O9,$Q$2:$Q$46,"Aprobada")>0,AND(Resumen!$B$15="La cursada aprobada",COUNTIFS($F$2:$F$46,O9,$Q$2:$Q$46,"Cursada aprobada")>0))),O9&" ","")&IF(NOT(OR(P9="",COUNTIF($F$2:$F$46,P9)=0,COUNTIFS($F$2:$F$46,P9,$Q$2:$Q$46,"Aprobada")>0,AND(Resumen!$B$15="La cursada aprobada",COUNTIFS($F$2:$F$46,P9,$Q$2:$Q$46,"Cursada aprobada")>0))),P9&" ","")),""))
A10: Ciclo básico | C10: 2 | D10: 1 | E10: AD | F10: 308 | G10: Funciones Organizacionales | H10: I | I10: 6 | K10: 96 | L10: 104 | Q10: No cursada | R10: =IF(Q10="Aprobada","Ya aprobada",IF(Q10="Cursada aprobada","Ya cursada",IF(AND(OR(L10="",COUNTIF($F$2:$F$46,L10)=0,COUNTIFS($F$2:$F$46,L10,$Q$2:$Q$46,"Aprobada")>0,AND(Resumen!$B$15="La cursada aprobada",COUNTIFS($F$2:$F$46,L10,$Q$2:$Q$46,"Cursada aprobada")>0)),OR(M10="",COUNTIF($F$2:$F$46,M10)=0,COUNTIFS($F$2:$F$46,M10,$Q$2:$Q$46,"Aprobada")>0,AND(Resumen!$B$15="La cursada aprobada",COUNTIFS($F$2:$F$46,M10,$Q$2:$Q$46,"Cursada aprobada")>0)),OR(N10="",COUNTIF($F$2:$F$46,N10)=0,COUNTIFS($F$2:$F$46,N10,$Q$2:$Q$46,"Aprobada")>0,AND(Resumen!$B$15="La cursada aprobada",COUNTIFS($F$2:$F$46,N10,$Q$2:$Q$46,"Cursada aprobada")>0)),OR(O10="",COUNTIF($F$2:$F$46,O10)=0,COUNTIFS($F$2:$F$46,O10,$Q$2:$Q$46,"Aprobada")>0,AND(Resumen!$B$15="La cursada aprobada",COUNTIFS($F$2:$F$46,O10,$Q$2:$Q$46,"Cursada aprobada")>0)),OR(P10="",COUNTIF($F$2:$F$46,P10)=0,COUNTIFS($F$2:$F$46,P10,$Q$2:$Q$46,"Aprobada")>0,AND(Resumen!$B$15="La cursada aprobada",COUNTIFS($F$2:$F$46,P10,$Q$2:$Q$46,"Cursada aprobada")>0))),"Sí","No"))) -> No | S10: =TRIM(IF(NOT(OR(L10="",COUNTIF($F$2:$F$46,L10)=0,COUNTIFS($F$2:$F$46,L10,$Q$2:$Q$46,"Aprobada")>0,AND(Resumen!$B$15="La cursada aprobada",COUNTIFS($F$2:$F$46,L10,$Q$2:$Q$46,"Cursada aprobada")>0))),L10&" ","")&IF(NOT(OR(M10="",COUNTIF($F$2:$F$46,M10)=0,COUNTIFS($F$2:$F$46,M10,$Q$2:$Q$46,"Aprobada")>0,AND(Resumen!$B$15="La cursada aprobada",COUNTIFS($F$2:$F$46,M10,$Q$2:$Q$46,"Cursada aprobada")>0))),M10&" ","")&IF(NOT(OR(N10="",COUNTIF($F$2:$F$46,N10)=0,COUNTIFS($F$2:$F$46,N10,$Q$2:$Q$46,"Aprobada")>0,AND(Resumen!$B$15="La cursada aprobada",COUNTIFS($F$2:$F$46,N10,$Q$2:$Q$46,"Cursada aprobada")>0))),N10&" ","")&IF(NOT(OR(O10="",COUNTIF($F$2:$F$46,O10)=0,COUNTIFS($F$2:$F$46,O10,$Q$2:$Q$46,"Aprobada")>0,AND(Resumen!$B$15="La cursada aprobada",COUNTIFS($F$2:$F$46,O10,$Q$2:$Q$46,"Cursada aprobada")>0))),O10&" ","")&IF(NOT(OR(P10="",COUNTIF($F$2:$F$46,P10)=0,COUNTIFS($F$2:$F$46,P10,$Q$2:$Q$46,"Aprobada")>0,AND(Resumen!$B$15="La cursada aprobada",COUNTIFS($F$2:$F$46,P10,$Q$2:$Q$46,"Cursada aprobada")>0))),P10&" ","")) -> 104 | T10: =IF(Q10="Cursada aprobada",IF(AND(OR(L10="",COUNTIF($F$2:$F$46,L10)=0,COUNTIFS($F$2:$F$46,L10,$Q$2:$Q$46,"Aprobada")>0),OR(M10="",COUNTIF($F$2:$F$46,M10)=0,COUNTIFS($F$2:$F$46,M10,$Q$2:$Q$46,"Aprobada")>0),OR(N10="",COUNTIF($F$2:$F$46,N10)=0,COUNTIFS($F$2:$F$46,N10,$Q$2:$Q$46,"Aprobada")>0),OR(O10="",COUNTIF($F$2:$F$46,O10)=0,COUNTIFS($F$2:$F$46,O10,$Q$2:$Q$46,"Aprobada")>0),OR(P10="",COUNTIF($F$2:$F$46,P10)=0,COUNTIFS($F$2:$F$46,P10,$Q$2:$Q$46,"Aprobada")>0)),"Sí","No"),"") | U10: =IF(Q10="Aprobada",TRIM(IF(NOT(OR(L10="",COUNTIF($F$2:$F$46,L10)=0,COUNTIFS($F$2:$F$46,L10,$Q$2:$Q$46,"Aprobada")>0)),L10&" ","")&IF(NOT(OR(M10="",COUNTIF($F$2:$F$46,M10)=0,COUNTIFS($F$2:$F$46,M10,$Q$2:$Q$46,"Aprobada")>0)),M10&" ","")&IF(NOT(OR(N10="",COUNTIF($F$2:$F$46,N10)=0,COUNTIFS($F$2:$F$46,N10,$Q$2:$Q$46,"Aprobada")>0)),N10&" ","")&IF(NOT(OR(O10="",COUNTIF($F$2:$F$46,O10)=0,COUNTIFS($F$2:$F$46,O10,$Q$2:$Q$46,"Aprobada")>0)),O10&" ","")&IF(NOT(OR(P10="",COUNTIF($F$2:$F$46,P10)=0,COUNTIFS($F$2:$F$46,P10,$Q$2:$Q$46,"Aprobada")>0)),P10&" ","")),IF(Q10="Cursada aprobada",TRIM(IF(NOT(OR(L10="",COUNTIF($F$2:$F$46,L10)=0,COUNTIFS($F$2:$F$46,L10,$Q$2:$Q$46,"Aprobada")>0,AND(Resumen!$B$15="La cursada aprobada",COUNTIFS($F$2:$F$46,L10,$Q$2:$Q$46,"Cursada aprobada")>0))),L10&" ","")&IF(NOT(OR(M10="",COUNTIF($F$2:$F$46,M10)=0,COUNTIFS($F$2:$F$46,M10,$Q$2:$Q$46,"Aprobada")>0,AND(Resumen!$B$15="La cursada aprobada",COUNTIFS($F$2:$F$46,M10,$Q$2:$Q$46,"Cursada aprobada")>0))),M10&" ","")&IF(NOT(OR(N10="",COUNTIF($F$2:$F$46,N10)=0,COUNTIFS($F$2:$F$46,N10,$Q$2:$Q$46,"Aprobada")>0,AND(Resumen!$B$15="La cursada aprobada",COUNTIFS($F$2:$F$46,N10,$Q$2:$Q$46,"Cursada aprobada")>0))),N10&" ","")&IF(NOT(OR(O10="",COUNTIF($F$2:$F$46,O10)=0,COUNTIFS($F$2:$F$46,O10,$Q$2:$Q$46,"Aprobada")>0,AND(Resumen!$B$15="La cursada aprobada",COUNTIFS($F$2:$F$46,O10,$Q$2:$Q$46,"Cursada aprobada")>0))),O10&" ","")&IF(NOT(OR(P10="",COUNTIF($F$2:$F$46,P10)=0,COUNTIFS($F$2:$F$46,P10,$Q$2:$Q$46,"Aprobada")>0,AND(Resumen!$B$15="La cursada aprobada",COUNTIFS($F$2:$F$46,P10,$Q$2:$Q$46,"Cursada aprobada")>0))),P10&" ","")),""))
A11: Ciclo básico | C11: 2 | D11: 1 | E11: CS | F11: 280 | G11: Historia Económica y Social II | H11: II | I11: 4 | K11: 64 | L11: 180 | Q11: No cursada | R11: =IF(Q11="Aprobada","Ya aprobada",IF(Q11="Cursada aprobada","Ya cursada",IF(AND(OR(L11="",COUNTIF($F$2:$F$46,L11)=0,COUNTIFS($F$2:$F$46,L11,$Q$2:$Q$46,"Aprobada")>0,AND(Resumen!$B$15="La cursada aprobada",COUNTIFS($F$2:$F$46,L11,$Q$2:$Q$46,"Cursada aprobada")>0)),OR(M11="",COUNTIF($F$2:$F$46,M11)=0,COUNTIFS($F$2:$F$46,M11,$Q$2:$Q$46,"Aprobada")>0,AND(Resumen!$B$15="La cursada aprobada",COUNTIFS($F$2:$F$46,M11,$Q$2:$Q$46,"Cursada aprobada")>0)),OR(N11="",COUNTIF($F$2:$F$46,N11)=0,COUNTIFS($F$2:$F$46,N11,$Q$2:$Q$46,"Aprobada")>0,AND(Resumen!$B$15="La cursada aprobada",COUNTIFS($F$2:$F$46,N11,$Q$2:$Q$46,"Cursada aprobada")>0)),OR(O11="",COUNTIF($F$2:$F$46,O11)=0,COUNTIFS($F$2:$F$46,O11,$Q$2:$Q$46,"Aprobada")>0,AND(Resumen!$B$15="La cursada aprobada",COUNTIFS($F$2:$F$46,O11,$Q$2:$Q$46,"Cursada aprobada")>0)),OR(P11="",COUNTIF($F$2:$F$46,P11)=0,COUNTIFS($F$2:$F$46,P11,$Q$2:$Q$46,"Aprobada")>0,AND(Resumen!$B$15="La cursada aprobada",COUNTIFS($F$2:$F$46,P11,$Q$2:$Q$46,"Cursada aprobada")>0))),"Sí","No"))) -> No | S11: =TRIM(IF(NOT(OR(L11="",COUNTIF($F$2:$F$46,L11)=0,COUNTIFS($F$2:$F$46,L11,$Q$2:$Q$46,"Aprobada")>0,AND(Resumen!$B$15="La cursada aprobada",COUNTIFS($F$2:$F$46,L11,$Q$2:$Q$46,"Cursada aprobada")>0))),L11&" ","")&IF(NOT(OR(M11="",COUNTIF($F$2:$F$46,M11)=0,COUNTIFS($F$2:$F$46,M11,$Q$2:$Q$46,"Aprobada")>0,AND(Resumen!$B$15="La cursada aprobada",COUNTIFS($F$2:$F$46,M11,$Q$2:$Q$46,"Cursada aprobada")>0))),M11&" ","")&IF(NOT(OR(N11="",COUNTIF($F$2:$F$46,N11)=0,COUNTIFS($F$2:$F$46,N11,$Q$2:$Q$46,"Aprobada")>0,AND(Resumen!$B$15="La cursada aprobada",COUNTIFS($F$2:$F$46,N11,$Q$2:$Q$46,"Cursada aprobada")>0))),N11&" ","")&IF(NOT(OR(O11="",COUNTIF($F$2:$F$46,O11)=0,COUNTIFS($F$2:$F$46,O11,$Q$2:$Q$46,"Aprobada")>0,AND(Resumen!$B$15="La cursada aprobada",COUNTIFS($F$2:$F$46,O11,$Q$2:$Q$46,"Cursada aprobada")>0))),O11&" ","")&IF(NOT(OR(P11="",COUNTIF($F$2:$F$46,P11)=0,COUNTIFS($F$2:$F$46,P11,$Q$2:$Q$46,"Aprobada")>0,AND(Resumen!$B$15="La cursada aprobada",COUNTIFS($F$2:$F$46,P11,$Q$2:$Q$46,"Cursada aprobada")>0))),P11&" ","")) -> 180 | T11: =IF(Q11="Cursada aprobada",IF(AND(OR(L11="",COUNTIF($F$2:$F$46,L11)=0,COUNTIFS($F$2:$F$46,L11,$Q$2:$Q$46,"Aprobada")>0),OR(M11="",COUNTIF($F$2:$F$46,M11)=0,COUNTIFS($F$2:$F$46,M11,$Q$2:$Q$46,"Aprobada")>0),OR(N11="",COUNTIF($F$2:$F$46,N11)=0,COUNTIFS($F$2:$F$46,N11,$Q$2:$Q$46,"Aprobada")>0),OR(O11="",COUNTIF($F$2:$F$46,O11)=0,COUNTIFS($F$2:$F$46,O11,$Q$2:$Q$46,"Aprobada")>0),OR(P11="",COUNTIF($F$2:$F$46,P11)=0,COUNTIFS($F$2:$F$46,P11,$Q$2:$Q$46,"Aprobada")>0)),"Sí","No"),"") | U11: =IF(Q11="Aprobada",TRIM(IF(NOT(OR(L11="",COUNTIF($F$2:$F$46,L11)=0,COUNTIFS($F$2:$F$46,L11,$Q$2:$Q$46,"Aprobada")>0)),L11&" ","")&IF(NOT(OR(M11="",COUNTIF($F$2:$F$46,M11)=0,COUNTIFS($F$2:$F$46,M11,$Q$2:$Q$46,"Aprobada")>0)),M11&" ","")&IF(NOT(OR(N11="",COUNTIF($F$2:$F$46,N11)=0,COUNTIFS($F$2:$F$46,N11,$Q$2:$Q$46,"Aprobada")>0)),N11&" ","")&IF(NOT(OR(O11="",COUNTIF($F$2:$F$46,O11)=0,COUNTIFS($F$2:$F$46,O11,$Q$2:$Q$46,"Aprobada")>0)),O11&" ","")&IF(NOT(OR(P11="",COUNTIF($F$2:$F$46,P11)=0,COUNTIFS($F$2:$F$46,P11,$Q$2:$Q$46,"Aprobada")>0)),P11&" ","")),IF(Q11="Cursada aprobada",TRIM(IF(NOT(OR(L11="",COUNTIF($F$2:$F$46,L11)=0,COUNTIFS($F$2:$F$46,L11,$Q$2:$Q$46,"Aprobada")>0,AND(Resumen!$B$15="La cursada aprobada",COUNTIFS($F$2:$F$46,L11,$Q$2:$Q$46,"Cursada aprobada")>0))),L11&" ","")&IF(NOT(OR(M11="",COUNTIF($F$2:$F$46,M11)=0,COUNTIFS($F$2:$F$46,M11,$Q$2:$Q$46,"Aprobada")>0,AND(Resumen!$B$15="La cursada aprobada",COUNTIFS($F$2:$F$46,M11,$Q$2:$Q$46,"Cursada aprobada")>0))),M11&" ","")&IF(NOT(OR(N11="",COUNTIF($F$2:$F$46,N11)=0,COUNTIFS($F$2:$F$46,N11,$Q$2:$Q$46,"Aprobada")>0,AND(Resumen!$B$15="La cursada aprobada",COUNTIFS($F$2:$F$46,N11,$Q$2:$Q$46,"Cursada aprobada")>0))),N11&" ","")&IF(NOT(OR(O11="",COUNTIF($F$2:$F$46,O11)=0,COUNTIFS($F$2:$F$46,O11,$Q$2:$Q$46,"Aprobada")>0,AND(Resumen!$B$15="La cursada aprobada",COUNTIFS($F$2:$F$46,O11,$Q$2:$Q$46,"Cursada aprobada")>0))),O11&" ","")&IF(NOT(OR(P11="",COUNTIF($F$2:$F$46,P11)=0,COUNTIFS($F$2:$F$46,P11,$Q$2:$Q$46,"Aprobada")>0,AND(Resumen!$B$15="La cursada aprobada",COUNTIFS($F$2:$F$46,P11,$Q$2:$Q$46,"Cursada aprobada")>0))),P11&" ","")),""))
A12: Ciclo básico | C12: 2 | D12: 1 | E12: JU | F12: 202 | G12: Derecho Constitucional | H12: II | I12: 4 | J12: 32 | Q12: No cursada | R12: =IF(Q12="Aprobada","Ya aprobada",IF(Q12="Cursada aprobada","Ya cursada",IF(AND(OR(L12="",COUNTIF($F$2:$F$46,L12)=0,COUNTIFS($F$2:$F$46,L12,$Q$2:$Q$46,"Aprobada")>0,AND(Resumen!$B$15="La cursada aprobada",COUNTIFS($F$2:$F$46,L12,$Q$2:$Q$46,"Cursada aprobada")>0)),OR(M12="",COUNTIF($F$2:$F$46,M12)=0,COUNTIFS($F$2:$F$46,M12,$Q$2:$Q$46,"Aprobada")>0,AND(Resumen!$B$15="La cursada aprobada",COUNTIFS($F$2:$F$46,M12,$Q$2:$Q$46,"Cursada aprobada")>0)),OR(N12="",COUNTIF($F$2:$F$46,N12)=0,COUNTIFS($F$2:$F$46,N12,$Q$2:$Q$46,"Aprobada")>0,AND(Resumen!$B$15="La cursada aprobada",COUNTIFS($F$2:$F$46,N12,$Q$2:$Q$46,"Cursada aprobada")>0)),OR(O12="",COUNTIF($F$2:$F$46,O12)=0,COUNTIFS($F$2:$F$46,O12,$Q$2:$Q$46,"Aprobada")>0,AND(Resumen!$B$15="La cursada aprobada",COUNTIFS($F$2:$F$46,O12,$Q$2:$Q$46,"Cursada aprobada")>0)),OR(P12="",COUNTIF($F$2:$F$46,P12)=0,COUNTIFS($F$2:$F$46,P12,$Q$2:$Q$46,"Aprobada")>0,AND(Resumen!$B$15="La cursada aprobada",COUNTIFS($F$2:$F$46,P12,$Q$2:$Q$46,"Cursada aprobada")>0))),"Sí","No"))) -> Sí | S12: =TRIM(IF(NOT(OR(L12="",COUNTIF($F$2:$F$46,L12)=0,COUNTIFS($F$2:$F$46,L12,$Q$2:$Q$46,"Aprobada")>0,AND(Resumen!$B$15="La cursada aprobada",COUNTIFS($F$2:$F$46,L12,$Q$2:$Q$46,"Cursada aprobada")>0))),L12&" ","")&IF(NOT(OR(M12="",COUNTIF($F$2:$F$46,M12)=0,COUNTIFS($F$2:$F$46,M12,$Q$2:$Q$46,"Aprobada")>0,AND(Resumen!$B$15="La cursada aprobada",COUNTIFS($F$2:$F$46,M12,$Q$2:$Q$46,"Cursada aprobada")>0))),M12&" ","")&IF(NOT(OR(N12="",COUNTIF($F$2:$F$46,N12)=0,COUNTIFS($F$2:$F$46,N12,$Q$2:$Q$46,"Aprobada")>0,AND(Resumen!$B$15="La cursada aprobada",COUNTIFS($F$2:$F$46,N12,$Q$2:$Q$46,"Cursada aprobada")>0))),N12&" ","")&IF(NOT(OR(O12="",COUNTIF($F$2:$F$46,O12)=0,COUNTIFS($F$2:$F$46,O12,$Q$2:$Q$46,"Aprobada")>0,AND(Resumen!$B$15="La cursada aprobada",COUNTIFS($F$2:$F$46,O12,$Q$2:$Q$46,"Cursada aprobada")>0))),O12&" ","")&IF(NOT(OR(P12="",COUNTIF($F$2:$F$46,P12)=0,COUNTIFS($F$2:$F$46,P12,$Q$2:$Q$46,"Aprobada")>0,AND(Resumen!$B$15="La cursada aprobada",COUNTIFS($F$2:$F$46,P12,$Q$2:$Q$46,"Cursada aprobada")>0))),P12&" ","")) | T12: =IF(Q12="Cursada aprobada",IF(AND(OR(L12="",COUNTIF($F$2:$F$46,L12)=0,COUNTIFS($F$2:$F$46,L12,$Q$2:$Q$46,"Aprobada")>0),OR(M12="",COUNTIF($F$2:$F$46,M12)=0,COUNTIFS($F$2:$F$46,M12,$Q$2:$Q$46,"Aprobada")>0),OR(N12="",COUNTIF($F$2:$F$46,N12)=0,COUNTIFS($F$2:$F$46,N12,$Q$2:$Q$46,"Aprobada")>0),OR(O12="",COUNTIF($F$2:$F$46,O12)=0,COUNTIFS($F$2:$F$46,O12,$Q$2:$Q$46,"Aprobada")>0),OR(P12="",COUNTIF($F$2:$F$46,P12)=0,COUNTIFS($F$2:$F$46,P12,$Q$2:$Q$46,"Aprobada")>0)),"Sí","No"),"") | U12: =IF(Q12="Aprobada",TRIM(IF(NOT(OR(L12="",COUNTIF($F$2:$F$46,L12)=0,COUNTIFS($F$2:$F$46,L12,$Q$2:$Q$46,"Aprobada")>0)),L12&" ","")&IF(NOT(OR(M12="",COUNTIF($F$2:$F$46,M12)=0,COUNTIFS($F$2:$F$46,M12,$Q$2:$Q$46,"Aprobada")>0)),M12&" ","")&IF(NOT(OR(N12="",COUNTIF($F$2:$F$46,N12)=0,COUNTIFS($F$2:$F$46,N12,$Q$2:$Q$46,"Aprobada")>0)),N12&" ","")&IF(NOT(OR(O12="",COUNTIF($F$2:$F$46,O12)=0,COUNTIFS($F$2:$F$46,O12,$Q$2:$Q$46,"Aprobada")>0)),O12&" ","")&IF(NOT(OR(P12="",COUNTIF($F$2:$F$46,P12)=0,COUNTIFS($F$2:$F$46,P12,$Q$2:$Q$46,"Aprobada")>0)),P12&" ","")),IF(Q12="Cursada aprobada",TRIM(IF(NOT(OR(L12="",COUNTIF($F$2:$F$46,L12)=0,COUNTIFS($F$2:$F$46,L12,$Q$2:$Q$46,"Aprobada")>0,AND(Resumen!$B$15="La cursada aprobada",COUNTIFS($F$2:$F$46,L12,$Q$2:$Q$46,"Cursada aprobada")>0))),L12&" ","")&IF(NOT(OR(M12="",COUNTIF($F$2:$F$46,M12)=0,COUNTIFS($F$2:$F$46,M12,$Q$2:$Q$46,"Aprobada")>0,AND(Resumen!$B$15="La cursada aprobada",COUNTIFS($F$2:$F$46,M12,$Q$2:$Q$46,"Cursada aprobada")>0))),M12&" ","")&IF(NOT(OR(N12="",COUNTIF($F$2:$F$46,N12)=0,COUNTIFS($F$2:$F$46,N12,$Q$2:$Q$46,"Aprobada")>0,AND(Resumen!$B$15="La cursada aprobada",COUNTIFS($F$2:$F$46,N12,$Q$2:$Q$46,"Cursada aprobada")>0))),N12&" ","")&IF(NOT(OR(O12="",COUNTIF($F$2:$F$46,O12)=0,COUNTIFS($F$2:$F$46,O12,$Q$2:$Q$46,"Aprobada")>0,AND(Resumen!$B$15="La cursada aprobada",COUNTIFS($F$2:$F$46,O12,$Q$2:$Q$46,"Cursada aprobada")>0))),O12&" ","")&IF(NOT(OR(P12="",COUNTIF($F$2:$F$46,P12)=0,COUNTIFS($F$2:$F$46,P12,$Q$2:$Q$46,"Aprobada")>0,AND(Resumen!$B$15="La cursada aprobada",COUNTIFS($F$2:$F$46,P12,$Q$2:$Q$46,"Cursada aprobada")>0))),P12&" ","")),""))
A13: Ciclo básico | C13: 2 | D13: 1 | E13: JU | F13: 307 | G13: Derecho Administrativo | H13: II | I13: 4 | J13: 32 | Q13: No cursada | R13: =IF(Q13="Aprobada","Ya aprobada",IF(Q13="Cursada aprobada","Ya cursada",IF(AND(OR(L13="",COUNTIF($F$2:$F$46,L13)=0,COUNTIFS($F$2:$F$46,L13,$Q$2:$Q$46,"Aprobada")>0,AND(Resumen!$B$15="La cursada aprobada",COUNTIFS($F$2:$F$46,L13,$Q$2:$Q$46,"Cursada aprobada")>0)),OR(M13="",COUNTIF($F$2:$F$46,M13)=0,COUNTIFS($F$2:$F$46,M13,$Q$2:$Q$46,"Aprobada")>0,AND(Resumen!$B$15="La cursada aprobada",COUNTIFS($F$2:$F$46,M13,$Q$2:$Q$46,"Cursada aprobada")>0)),OR(N13="",COUNTIF($F$2:$F$46,N13)=0,COUNTIFS($F$2:$F$46,N13,$Q$2:$Q$46,"Aprobada")>0,AND(Resumen!$B$15="La cursada aprobada",COUNTIFS($F$2:$F$46,N13,$Q$2:$Q$46,"Cursada aprobada")>0)),OR(O13="",COUNTIF($F$2:$F$46,O13)=0,COUNTIFS($F$2:$F$46,O13,$Q$2:$Q$46,"Aprobada")>0,AND(Resumen!$B$15="La cursada aprobada",COUNTIFS($F$2:$F$46,O13,$Q$2:$Q$46,"Cursada aprobada")>0)),OR(P13="",COUNTIF($F$2:$F$46,P13)=0,COUNTIFS($F$2:$F$46,P13,$Q$2:$Q$46,"Aprobada")>0,AND(Resumen!$B$15="La cursada aprobada",COUNTIFS($F$2:$F$46,P13,$Q$2:$Q$46,"Cursada aprobada")>0))),"Sí","No"))) -> Sí | S13: =TRIM(IF(NOT(OR(L13="",COUNTIF($F$2:$F$46,L13)=0,COUNTIFS($F$2:$F$46,L13,$Q$2:$Q$46,"Aprobada")>0,AND(Resumen!$B$15="La cursada aprobada",COUNTIFS($F$2:$F$46,L13,$Q$2:$Q$46,"Cursada aprobada")>0))),L13&" ","")&IF(NOT(OR(M13="",COUNTIF($F$2:$F$46,M13)=0,COUNTIFS($F$2:$F$46,M13,$Q$2:$Q$46,"Aprobada")>0,AND(Resumen!$B$15="La cursada aprobada",COUNTIFS($F$2:$F$46,M13,$Q$2:$Q$46,"Cursada aprobada")>0))),M13&" ","")&IF(NOT(OR(N13="",COUNTIF($F$2:$F$46,N13)=0,COUNTIFS($F$2:$F$46,N13,$Q$2:$Q$46,"Aprobada")>0,AND(Resumen!$B$15="La cursada aprobada",COUNTIFS($F$2:$F$46,N13,$Q$2:$Q$46,"Cursada aprobada")>0))),N13&" ","")&IF(NOT(OR(O13="",COUNTIF($F$2:$F$46,O13)=0,COUNTIFS($F$2:$F$46,O13,$Q$2:$Q$46,"Aprobada")>0,AND(Resumen!$B$15="La cursada aprobada",COUNTIFS($F$2:$F$46,O13,$Q$2:$Q$46,"Cursada aprobada")>0))),O13&" ","")&IF(NOT(OR(P13="",COUNTIF($F$2:$F$46,P13)=0,COUNTIFS($F$2:$F$46,P13,$Q$2:$Q$46,"Aprobada")>0,AND(Resumen!$B$15="La cursada aprobada",COUNTIFS($F$2:$F$46,P13,$Q$2:$Q$46,"Cursada aprobada")>0))),P13&" ","")) | T13: =IF(Q13="Cursada aprobada",IF(AND(OR(L13="",COUNTIF($F$2:$F$46,L13)=0,COUNTIFS($F$2:$F$46,L13,$Q$2:$Q$46,"Aprobada")>0),OR(M13="",COUNTIF($F$2:$F$46,M13)=0,COUNTIFS($F$2:$F$46,M13,$Q$2:$Q$46,"Aprobada")>0),OR(N13="",COUNTIF($F$2:$F$46,N13)=0,COUNTIFS($F$2:$F$46,N13,$Q$2:$Q$46,"Aprobada")>0),OR(O13="",COUNTIF($F$2:$F$46,O13)=0,COUNTIFS($F$2:$F$46,O13,$Q$2:$Q$46,"Aprobada")>0),OR(P13="",COUNTIF($F$2:$F$46,P13)=0,COUNTIFS($F$2:$F$46,P13,$Q$2:$Q$46,"Aprobada")>0)),"Sí","No"),"") | U13: =IF(Q13="Aprobada",TRIM(IF(NOT(OR(L13="",COUNTIF($F$2:$F$46,L13)=0,COUNTIFS($F$2:$F$46,L13,$Q$2:$Q$46,"Aprobada")>0)),L13&" ","")&IF(NOT(OR(M13="",COUNTIF($F$2:$F$46,M13)=0,COUNTIFS($F$2:$F$46,M13,$Q$2:$Q$46,"Aprobada")>0)),M13&" ","")&IF(NOT(OR(N13="",COUNTIF($F$2:$F$46,N13)=0,COUNTIFS($F$2:$F$46,N13,$Q$2:$Q$46,"Aprobada")>0)),N13&" ","")&IF(NOT(OR(O13="",COUNTIF($F$2:$F$46,O13)=0,COUNTIFS($F$2:$F$46,O13,$Q$2:$Q$46,"Aprobada")>0)),O13&" ","")&IF(NOT(OR(P13="",COUNTIF($F$2:$F$46,P13)=0,COUNTIFS($F$2:$F$46,P13,$Q$2:$Q$46,"Aprobada")>0)),P13&" ","")),IF(Q13="Cursada aprobada",TRIM(IF(NOT(OR(L13="",COUNTIF($F$2:$F$46,L13)=0,COUNTIFS($F$2:$F$46,L13,$Q$2:$Q$46,"Aprobada")>0,AND(Resumen!$B$15="La cursada aprobada",COUNTIFS($F$2:$F$46,L13,$Q$2:$Q$46,"Cursada aprobada")>0))),L13&" ","")&IF(NOT(OR(M13="",COUNTIF($F$2:$F$46,M13)=0,COUNTIFS($F$2:$F$46,M13,$Q$2:$Q$46,"Aprobada")>0,AND(Resumen!$B$15="La cursada aprobada",COUNTIFS($F$2:$F$46,M13,$Q$2:$Q$46,"Cursada aprobada")>0))),M13&" ","")&IF(NOT(OR(N13="",COUNTIF($F$2:$F$46,N13)=0,COUNTIFS($F$2:$F$46,N13,$Q$2:$Q$46,"Aprobada")>0,AND(Resumen!$B$15="La cursada aprobada",COUNTIFS($F$2:$F$46,N13,$Q$2:$Q$46,"Cursada aprobada")>0))),N13&" ","")&IF(NOT(OR(O13="",COUNTIF($F$2:$F$46,O13)=0,COUNTIFS($F$2:$F$46,O13,$Q$2:$Q$46,"Aprobada")>0,AND(Resumen!$B$15="La cursada aprobada",COUNTIFS($F$2:$F$46,O13,$Q$2:$Q$46,"Cursada aprobada")>0))),O13&" ","")&IF(NOT(OR(P13="",COUNTIF($F$2:$F$46,P13)=0,COUNTIFS($F$2:$F$46,P13,$Q$2:$Q$46,"Aprobada")>0,AND(Resumen!$B$15="La cursada aprobada",COUNTIFS($F$2:$F$46,P13,$Q$2:$Q$46,"Cursada aprobada")>0))),P13&" ","")),""))
A14: Ciclo básico | C14: 2 | D14: 2 | E14: CO | F14: 210 | G14: Contabilidad II | H14: I | I14: 6 | K14: 96 | L14: 103 | Q14: No cursada | R14: =IF(Q14="Aprobada","Ya aprobada",IF(Q14="Cursada aprobada","Ya cursada",IF(AND(OR(L14="",COUNTIF($F$2:$F$46,L14)=0,COUNTIFS($F$2:$F$46,L14,$Q$2:$Q$46,"Aprobada")>0,AND(Resumen!$B$15="La cursada aprobada",COUNTIFS($F$2:$F$46,L14,$Q$2:$Q$46,"Cursada aprobada")>0)),OR(M14="",COUNTIF($F$2:$F$46,M14)=0,COUNTIFS($F$2:$F$46,M14,$Q$2:$Q$46,"Aprobada")>0,AND(Resumen!$B$15="La cursada aprobada",COUNTIFS($F$2:$F$46,M14,$Q$2:$Q$46,"Cursada aprobada")>0)),OR(N14="",COUNTIF($F$2:$F$46,N14)=0,COUNTIFS($F$2:$F$46,N14,$Q$2:$Q$46,"Aprobada")>0,AND(Resumen!$B$15="La cursada aprobada",COUNTIFS($F$2:$F$46,N14,$Q$2:$Q$46,"Cursada aprobada")>0)),OR(O14="",COUNTIF($F$2:$F$46,O14)=0,COUNTIFS($F$2:$F$46,O14,$Q$2:$Q$46,"Aprobada")>0,AND(Resumen!$B$15="La cursada aprobada",COUNTIFS($F$2:$F$46,O14,$Q$2:$Q$46,"Cursada aprobada")>0)),OR(P14="",COUNTIF($F$2:$F$46,P14)=0,COUNTIFS($F$2:$F$46,P14,$Q$2:$Q$46,"Aprobada")>0,AND(Resumen!$B$15="La cursada aprobada",COUNTIFS($F$2:$F$46,P14,$Q$2:$Q$46,"Cursada aprobada")>0))),"Sí","No"))) -> No | S14: =TRIM(IF(NOT(OR(L14="",COUNTIF($F$2:$F$46,L14)=0,COUNTIFS($F$2:$F$46,L14,$Q$2:$Q$46,"Aprobada")>0,AND(Resumen!$B$15="La cursada aprobada",COUNTIFS($F$2:$F$46,L14,$Q$2:$Q$46,"Cursada aprobada")>0))),L14&" ","")&IF(NOT(OR(M14="",COUNTIF($F$2:$F$46,M14)=0,COUNTIFS($F$2:$F$46,M14,$Q$2:$Q$46,"Aprobada")>0,AND(Resumen!$B$15="La cursada aprobada",COUNTIFS($F$2:$F$46,M14,$Q$2:$Q$46,"Cursada aprobada")>0))),M14&" ","")&IF(NOT(OR(N14="",COUNTIF($F$2:$F$46,N14)=0,COUNTIFS($F$2:$F$46,N14,$Q$2:$Q$46,"Aprobada")>0,AND(Resumen!$B$15="La cursada aprobada",COUNTIFS($F$2:$F$46,N14,$Q$2:$Q$46,"Cursada aprobada")>0))),N14&" ","")&IF(NOT(OR(O14="",COUNTIF($F$2:$F$46,O14)=0,COUNTIFS($F$2:$F$46,O14,$Q$2:$Q$46,"Aprobada")>0,AND(Resumen!$B$15="La cursada aprobada",COUNTIFS($F$2:$F$46,O14,$Q$2:$Q$46,"Cursada aprobada")>0))),O14&" ","")&IF(NOT(OR(P14="",COUNTIF($F$2:$F$46,P14)=0,COUNTIFS($F$2:$F$46,P14,$Q$2:$Q$46,"Aprobada")>0,AND(Resumen!$B$15="La cursada aprobada",COUNTIFS($F$2:$F$46,P14,$Q$2:$Q$46,"Cursada aprobada")>0))),P14&" ","")) -> 103 | T14: =IF(Q14="Cursada aprobada",IF(AND(OR(L14="",COUNTIF($F$2:$F$46,L14)=0,COUNTIFS($F$2:$F$46,L14,$Q$2:$Q$46,"Aprobada")>0),OR(M14="",COUNTIF($F$2:$F$46,M14)=0,COUNTIFS($F$2:$F$46,M14,$Q$2:$Q$46,"Aprobada")>0),OR(N14="",COUNTIF($F$2:$F$46,N14)=0,COUNTIFS($F$2:$F$46,N14,$Q$2:$Q$46,"Aprobada")>0),OR(O14="",COUNTIF($F$2:$F$46,O14)=0,COUNTIFS($F$2:$F$46,O14,$Q$2:$Q$46,"Aprobada")>0),OR(P14="",COUNTIF($F$2:$F$46,P14)=0,COUNTIFS($F$2:$F$46,P14,$Q$2:$Q$46,"Aprobada")>0)),"Sí","No"),"") | U14: =IF(Q14="Aprobada",TRIM(IF(NOT(OR(L14="",COUNTIF($F$2:$F$46,L14)=0,COUNTIFS($F$2:$F$46,L14,$Q$2:$Q$46,"Aprobada")>0)),L14&" ","")&IF(NOT(OR(M14="",COUNTIF($F$2:$F$46,M14)=0,COUNTIFS($F$2:$F$46,M14,$Q$2:$Q$46,"Aprobada")>0)),M14&" ","")&IF(NOT(OR(N14="",COUNTIF($F$2:$F$46,N14)=0,COUNTIFS($F$2:$F$46,N14,$Q$2:$Q$46,"Aprobada")>0)),N14&" ","")&IF(NOT(OR(O14="",COUNTIF($F$2:$F$46,O14)=0,COUNTIFS($F$2:$F$46,O14,$Q$2:$Q$46,"Aprobada")>0)),O14&" ","")&IF(NOT(OR(P14="",COUNTIF($F$2:$F$46,P14)=0,COUNTIFS($F$2:$F$46,P14,$Q$2:$Q$46,"Aprobada")>0)),P14&" ","")),IF(Q14="Cursada aprobada",TRIM(IF(NOT(OR(L14="",COUNTIF($F$2:$F$46,L14)=0,COUNTIFS($F$2:$F$46,L14,$Q$2:$Q$46,"Aprobada")>0,AND(Resumen!$B$15="La cursada aprobada",COUNTIFS($F$2:$F$46,L14,$Q$2:$Q$46,"Cursada aprobada")>0))),L14&" ","")&IF(NOT(OR(M14="",COUNTIF($F$2:$F$46,M14)=0,COUNTIFS($F$2:$F$46,M14,$Q$2:$Q$46,"Aprobada")>0,AND(Resumen!$B$15="La cursada aprobada",COUNTIFS($F$2:$F$46,M14,$Q$2:$Q$46,"Cursada aprobada")>0))),M14&" ","")&IF(NOT(OR(N14="",COUNTIF($F$2:$F$46,N14)=0,COUNTIFS($F$2:$F$46,N14,$Q$2:$Q$46,"Aprobada")>0,AND(Resumen!$B$15="La cursada aprobada",COUNTIFS($F$2:$F$46,N14,$Q$2:$Q$46,"Cursada aprobada")>0))),N14&" ","")&IF(NOT(OR(O14="",COUNTIF($F$2:$F$46,O14)=0,COUNTIFS($F$2:$F$46,O14,$Q$2:$Q$46,"Aprobada")>0,AND(Resumen!$B$15="La cursada aprobada",COUNTIFS($F$2:$F$46,O14,$Q$2:$Q$46,"Cursada aprobada")>0))),O14&" ","")&IF(NOT(OR(P14="",COUNTIF($F$2:$F$46,P14)=0,COUNTIFS($F$2:$F$46,P14,$Q$2:$Q$46,"Aprobada")>0,AND(Resumen!$B$15="La cursada aprobada",COUNTIFS($F$2:$F$46,P14,$Q$2:$Q$46,"Cursada aprobada")>0))),P14&" ","")),""))
